{
 "cells": [
  {
   "cell_type": "code",
   "execution_count": 6,
   "id": "525d05f9",
   "metadata": {},
   "outputs": [
    {
     "name": "stderr",
     "output_type": "stream",
     "text": [
      "<>:17: SyntaxWarning: \"is\" with a literal. Did you mean \"==\"?\n",
      "<>:17: SyntaxWarning: \"is\" with a literal. Did you mean \"==\"?\n",
      "<ipython-input-6-718938d24814>:17: SyntaxWarning: \"is\" with a literal. Did you mean \"==\"?\n",
      "  if faces is ():\n"
     ]
    },
    {
     "name": "stdout",
     "output_type": "stream",
     "text": [
      "Face not found\n",
      "Collecting Samples Complete\n"
     ]
    }
   ],
   "source": [
    "import cv2\n",
    "import numpy as np\n",
    "import threading\n",
    "\n",
    "\n",
    "# Load HAAR face classifier\n",
    "face_classifier = cv2.CascadeClassifier('haarcascade_frontalface_default.xml')\n",
    "\n",
    "# Load functions\n",
    "def face_extractor(img):\n",
    "    # Function detects faces and returns the cropped face\n",
    "    # If no face detected, it returns the input image\n",
    "    \n",
    "    gray = cv2.cvtColor(img,cv2.COLOR_BGR2GRAY)\n",
    "    faces = face_classifier.detectMultiScale(gray, 1.3, 5)\n",
    "    \n",
    "    if faces is ():\n",
    "        return None\n",
    "    \n",
    "    # Crop all faces found\n",
    "    for (x,y,w,h) in faces:\n",
    "        cropped_face = img[y:y+h, x:x+w]\n",
    "\n",
    "    return cropped_face\n",
    "\n",
    "# Initialize Webcam\n",
    "cap = cv2.VideoCapture(0)\n",
    "count = 0\n",
    "\n",
    "# Collect 100 samples of your face from webcam input\n",
    "while True:\n",
    "\n",
    "    ret, frame = cap.read()\n",
    "    if face_extractor(frame) is not None:\n",
    "        count += 1\n",
    "        face = cv2.resize(face_extractor(frame), (200, 200))\n",
    "        face = cv2.cvtColor(face, cv2.COLOR_BGR2GRAY)\n",
    "\n",
    "        # Save file in specified directory with unique name\n",
    "        file_name_path = './faces/user/' + str(count) + '.jpg'\n",
    "        cv2.imwrite(file_name_path, face)\n",
    "\n",
    "        # Put count on images and display live count\n",
    "        cv2.putText(face, str(count), (50, 50), cv2.FONT_HERSHEY_COMPLEX, 1, (0,255,0), 2)\n",
    "        cv2.imshow('Face Cropper', face)\n",
    "        \n",
    "    else:\n",
    "        print(\"Face not found\")\n",
    "        pass\n",
    "\n",
    "    if cv2.waitKey(1) == 13 or count == 100: #13 is the Enter Key\n",
    "        break\n",
    "        \n",
    "cap.release()\n",
    "cv2.destroyAllWindows()      \n",
    "print(\"Collecting Samples Complete\")"
   ]
  },
  {
   "cell_type": "code",
   "execution_count": 7,
   "id": "94e65cb7",
   "metadata": {},
   "outputs": [],
   "source": [
    "cap.release()"
   ]
  },
  {
   "cell_type": "code",
   "execution_count": 8,
   "id": "63ca5129",
   "metadata": {},
   "outputs": [
    {
     "name": "stdout",
     "output_type": "stream",
     "text": [
      "Model trained sucessefully\n"
     ]
    }
   ],
   "source": [
    "import cv2\n",
    "import numpy as np\n",
    "from os import listdir\n",
    "from os.path import isfile, join\n",
    "\n",
    "# Get the training data we previously made\n",
    "data_path = './faces/user/'\n",
    "onlyfiles = [f for f in listdir(data_path) if isfile(join(data_path, f))]\n",
    "\n",
    "# Create arrays for training data and labels\n",
    "Training_Data, Labels = [], []\n",
    "\n",
    "# Open training images in our datapath\n",
    "# Create a numpy array for training data\n",
    "for i, files in enumerate(onlyfiles):\n",
    "    image_path = data_path + onlyfiles[i]\n",
    "    images = cv2.imread(image_path, cv2.IMREAD_GRAYSCALE)\n",
    "    Training_Data.append(np.asarray(images, dtype=np.uint8))\n",
    "    Labels.append(i)\n",
    "\n",
    "# Create a numpy array for both training data and labels\n",
    "Labels = np.asarray(Labels, dtype=np.int32)\n",
    "\n",
    "# Initialize facial recognizer\n",
    "# model = cv2.face.createLBPHFaceRecognizer()\n",
    "# NOTE: For OpenCV 3.0 use cv2.face.createLBPHFaceRecognizer()\n",
    "# pip install opencv-contrib-python\n",
    "# model = cv2.createLBPHFaceRecognizer()\n",
    "ishika_model  = cv2.face_LBPHFaceRecognizer.create()\n",
    "# Let's train our model \n",
    "ishika_model.train(np.asarray(Training_Data), np.asarray(Labels))\n",
    "print(\"Model trained sucessefully\")\n"
   ]
  },
  {
   "cell_type": "code",
   "execution_count": 9,
   "id": "3ef0252e",
   "metadata": {},
   "outputs": [],
   "source": [
    "\n",
    "#mail function\n",
    "def mail():\n",
    "    os.system(\"python mail.py\")\n",
    "#Whatsapp function\n",
    "def whatsapp():\n",
    "    os.system(\"python whatsapp.py\")\n",
    "    "
   ]
  },
  {
   "cell_type": "code",
   "execution_count": 12,
   "id": "f83d84c2",
   "metadata": {},
   "outputs": [
    {
     "name": "stderr",
     "output_type": "stream",
     "text": [
      "<>:13: SyntaxWarning: \"is\" with a literal. Did you mean \"==\"?\n",
      "<>:13: SyntaxWarning: \"is\" with a literal. Did you mean \"==\"?\n",
      "<ipython-input-12-509cc63239a3>:13: SyntaxWarning: \"is\" with a literal. Did you mean \"==\"?\n",
      "  if faces is ():\n",
      "Exception in thread Exception in thread Thread-12:\n",
      "Traceback (most recent call last):\n",
      "  File \"C:\\Users\\Ishika\\anaconda3\\lib\\threading.py\", line 932, in _bootstrap_inner\n",
      "Thread-13:\n",
      "Traceback (most recent call last):\n",
      "  File \"C:\\Users\\Ishika\\anaconda3\\lib\\threading.py\", line 932, in _bootstrap_inner\n",
      "        self.run()\n",
      "self.run()\n",
      "  File \"C:\\Users\\Ishika\\anaconda3\\lib\\threading.py\", line 870, in run\n",
      "  File \"C:\\Users\\Ishika\\anaconda3\\lib\\threading.py\", line 870, in run\n",
      "    self._target(*self._args, **self._kwargs)\n",
      "TypeError: 'Thread' object is not callable\n",
      "    self._target(*self._args, **self._kwargs)\n",
      "TypeError: 'Thread' object is not callable\n",
      "Exception in thread Thread-14:\n",
      "Traceback (most recent call last):\n",
      "  File \"C:\\Users\\Ishika\\anaconda3\\lib\\threading.py\", line 932, in _bootstrap_inner\n",
      "Exception in thread Thread-15:\n",
      "Traceback (most recent call last):\n",
      "  File \"C:\\Users\\Ishika\\anaconda3\\lib\\threading.py\", line 932, in _bootstrap_inner\n",
      "    self.run()\n",
      "  File \"C:\\Users\\Ishika\\anaconda3\\lib\\threading.py\", line 870, in run\n",
      "    self.run()\n",
      "  File \"C:\\Users\\Ishika\\anaconda3\\lib\\threading.py\", line 870, in run\n",
      "    self._target(*self._args, **self._kwargs)\n",
      "TypeError: 'Thread' object is not callable\n",
      "    self._target(*self._args, **self._kwargs)\n",
      "TypeError: 'Thread' object is not callable\n",
      "Exception in thread Thread-16:\n",
      "Traceback (most recent call last):\n",
      "  File \"C:\\Users\\Ishika\\anaconda3\\lib\\threading.py\", line 932, in _bootstrap_inner\n",
      "Exception in thread Thread-17:\n",
      "Traceback (most recent call last):\n",
      "  File \"C:\\Users\\Ishika\\anaconda3\\lib\\threading.py\", line 932, in _bootstrap_inner\n",
      "    self.run()\n",
      "  File \"C:\\Users\\Ishika\\anaconda3\\lib\\threading.py\", line 870, in run\n",
      "    self.run()\n",
      "  File \"C:\\Users\\Ishika\\anaconda3\\lib\\threading.py\", line 870, in run\n",
      "    self._target(*self._args, **self._kwargs)\n",
      "TypeError: 'Thread' object is not callable\n",
      "    self._target(*self._args, **self._kwargs)\n",
      "TypeError: 'Thread' object is not callable\n",
      "Exception in thread Thread-18:\n",
      "Traceback (most recent call last):\n",
      "  File \"C:\\Users\\Ishika\\anaconda3\\lib\\threading.py\", line 932, in _bootstrap_inner\n",
      "Exception in thread Thread-19:\n",
      "Traceback (most recent call last):\n",
      "  File \"C:\\Users\\Ishika\\anaconda3\\lib\\threading.py\", line 932, in _bootstrap_inner\n",
      "    self.run()\n",
      "  File \"C:\\Users\\Ishika\\anaconda3\\lib\\threading.py\", line 870, in run\n",
      "    self.run()\n",
      "  File \"C:\\Users\\Ishika\\anaconda3\\lib\\threading.py\", line 870, in run\n",
      "        self._target(*self._args, **self._kwargs)\n",
      "TypeError: 'Thread' object is not callable\n",
      "self._target(*self._args, **self._kwargs)\n",
      "TypeError: 'Thread' object is not callable\n",
      "Exception in thread Thread-20:\n",
      "Traceback (most recent call last):\n",
      "  File \"C:\\Users\\Ishika\\anaconda3\\lib\\threading.py\", line 932, in _bootstrap_inner\n",
      "Exception in thread Thread-21:\n",
      "Traceback (most recent call last):\n",
      "  File \"C:\\Users\\Ishika\\anaconda3\\lib\\threading.py\", line 932, in _bootstrap_inner\n",
      "        self.run()\n",
      "  File \"C:\\Users\\Ishika\\anaconda3\\lib\\threading.py\", line 870, in run\n",
      "self.run()\n",
      "  File \"C:\\Users\\Ishika\\anaconda3\\lib\\threading.py\", line 870, in run\n",
      "    self._target(*self._args, **self._kwargs)\n",
      "TypeError: 'Thread' object is not callable\n",
      "    self._target(*self._args, **self._kwargs)\n",
      "TypeError: 'Thread' object is not callable\n",
      "Exception in thread Thread-22:\n",
      "Traceback (most recent call last):\n",
      "  File \"C:\\Users\\Ishika\\anaconda3\\lib\\threading.py\", line 932, in _bootstrap_inner\n",
      "Exception in thread Thread-23:\n",
      "Traceback (most recent call last):\n",
      "  File \"C:\\Users\\Ishika\\anaconda3\\lib\\threading.py\", line 932, in _bootstrap_inner\n",
      "    self.run()\n",
      "  File \"C:\\Users\\Ishika\\anaconda3\\lib\\threading.py\", line 870, in run\n",
      "    self.run()\n",
      "  File \"C:\\Users\\Ishika\\anaconda3\\lib\\threading.py\", line 870, in run\n",
      "    self._target(*self._args, **self._kwargs)\n",
      "TypeError: 'Thread' object is not callable\n",
      "    self._target(*self._args, **self._kwargs)\n",
      "TypeError: 'Thread' object is not callable\n",
      "Exception in thread Thread-24:\n",
      "Traceback (most recent call last):\n",
      "  File \"C:\\Users\\Ishika\\anaconda3\\lib\\threading.py\", line 932, in _bootstrap_inner\n",
      "Exception in thread Thread-25:\n",
      "Traceback (most recent call last):\n",
      "  File \"C:\\Users\\Ishika\\anaconda3\\lib\\threading.py\", line 932, in _bootstrap_inner\n",
      "    self.run()\n",
      "  File \"C:\\Users\\Ishika\\anaconda3\\lib\\threading.py\", line 870, in run\n",
      "    self.run()\n",
      "  File \"C:\\Users\\Ishika\\anaconda3\\lib\\threading.py\", line 870, in run\n",
      "    self._target(*self._args, **self._kwargs)\n",
      "TypeError: 'Thread' object is not callable\n",
      "    self._target(*self._args, **self._kwargs)\n",
      "TypeError: 'Thread' object is not callable\n",
      "Exception in thread Thread-26:\n",
      "Traceback (most recent call last):\n",
      "  File \"C:\\Users\\Ishika\\anaconda3\\lib\\threading.py\", line 932, in _bootstrap_inner\n",
      "Exception in thread Thread-27:\n",
      "Traceback (most recent call last):\n",
      "  File \"C:\\Users\\Ishika\\anaconda3\\lib\\threading.py\", line 932, in _bootstrap_inner\n",
      "    self.run()\n",
      "  File \"C:\\Users\\Ishika\\anaconda3\\lib\\threading.py\", line 870, in run\n",
      "    self.run()\n",
      "  File \"C:\\Users\\Ishika\\anaconda3\\lib\\threading.py\", line 870, in run\n",
      "        self._target(*self._args, **self._kwargs)\n",
      "TypeError: 'Thread' object is not callable\n",
      "self._target(*self._args, **self._kwargs)\n",
      "TypeError: 'Thread' object is not callable\n",
      "Exception in thread Thread-28Exception in thread :\n",
      "Thread-29:\n",
      "Traceback (most recent call last):\n",
      "  File \"C:\\Users\\Ishika\\anaconda3\\lib\\threading.py\", line 932, in _bootstrap_inner\n",
      "Traceback (most recent call last):\n",
      "  File \"C:\\Users\\Ishika\\anaconda3\\lib\\threading.py\", line 932, in _bootstrap_inner\n",
      "        self.run()\n",
      "  File \"C:\\Users\\Ishika\\anaconda3\\lib\\threading.py\", line 870, in run\n",
      "self.run()\n",
      "  File \"C:\\Users\\Ishika\\anaconda3\\lib\\threading.py\", line 870, in run\n",
      "        self._target(*self._args, **self._kwargs)\n",
      "TypeError: 'Thread' object is not callable\n",
      "self._target(*self._args, **self._kwargs)\n",
      "TypeError: 'Thread' object is not callable\n",
      "Exception in thread Exception in thread Thread-30:\n",
      "Traceback (most recent call last):\n",
      "  File \"C:\\Users\\Ishika\\anaconda3\\lib\\threading.py\", line 932, in _bootstrap_inner\n",
      "Thread-31:\n",
      "Traceback (most recent call last):\n",
      "  File \"C:\\Users\\Ishika\\anaconda3\\lib\\threading.py\", line 932, in _bootstrap_inner\n",
      "    self.run()    \n",
      "  File \"C:\\Users\\Ishika\\anaconda3\\lib\\threading.py\", line 870, in run\n",
      "self.run()\n",
      "  File \"C:\\Users\\Ishika\\anaconda3\\lib\\threading.py\", line 870, in run\n",
      "    self._target(*self._args, **self._kwargs)\n",
      "TypeError: 'Thread' object is not callable\n",
      "    self._target(*self._args, **self._kwargs)\n",
      "TypeError: 'Thread' object is not callable\n",
      "Exception in thread Thread-32:\n",
      "Traceback (most recent call last):\n",
      "  File \"C:\\Users\\Ishika\\anaconda3\\lib\\threading.py\", line 932, in _bootstrap_inner\n",
      "Exception in thread Thread-33:\n",
      "Traceback (most recent call last):\n",
      "  File \"C:\\Users\\Ishika\\anaconda3\\lib\\threading.py\", line 932, in _bootstrap_inner\n",
      "    self.run()\n",
      "  File \"C:\\Users\\Ishika\\anaconda3\\lib\\threading.py\", line 870, in run\n",
      "    self.run()\n",
      "  File \"C:\\Users\\Ishika\\anaconda3\\lib\\threading.py\", line 870, in run\n",
      "    self._target(*self._args, **self._kwargs)\n",
      "TypeError: 'Thread' object is not callable\n",
      "    self._target(*self._args, **self._kwargs)\n",
      "TypeError: 'Thread' object is not callable\n",
      "Exception in thread Thread-34:\n",
      "Traceback (most recent call last):\n",
      "  File \"C:\\Users\\Ishika\\anaconda3\\lib\\threading.py\", line 932, in _bootstrap_inner\n",
      "Exception in thread Thread-35:\n",
      "Traceback (most recent call last):\n",
      "  File \"C:\\Users\\Ishika\\anaconda3\\lib\\threading.py\", line 932, in _bootstrap_inner\n",
      "    self.run()\n",
      "  File \"C:\\Users\\Ishika\\anaconda3\\lib\\threading.py\", line 870, in run\n",
      "    self.run()\n",
      "  File \"C:\\Users\\Ishika\\anaconda3\\lib\\threading.py\", line 870, in run\n",
      "        self._target(*self._args, **self._kwargs)\n",
      "TypeError: 'Thread' object is not callable\n",
      "self._target(*self._args, **self._kwargs)\n",
      "TypeError: 'Thread' object is not callable\n",
      "Exception in thread Exception in thread Thread-36:\n",
      "Traceback (most recent call last):\n",
      "  File \"C:\\Users\\Ishika\\anaconda3\\lib\\threading.py\", line 932, in _bootstrap_inner\n",
      "Thread-37:\n",
      "Traceback (most recent call last):\n",
      "  File \"C:\\Users\\Ishika\\anaconda3\\lib\\threading.py\", line 932, in _bootstrap_inner\n",
      "        self.run()\n",
      "  File \"C:\\Users\\Ishika\\anaconda3\\lib\\threading.py\", line 870, in run\n",
      "self.run()\n",
      "  File \"C:\\Users\\Ishika\\anaconda3\\lib\\threading.py\", line 870, in run\n",
      "    self._target(*self._args, **self._kwargs)\n",
      "TypeError: 'Thread' object is not callable\n"
     ]
    },
    {
     "name": "stderr",
     "output_type": "stream",
     "text": [
      "    self._target(*self._args, **self._kwargs)\n",
      "TypeError: 'Thread' object is not callable\n",
      "Exception in thread Thread-38:\n",
      "Traceback (most recent call last):\n",
      "  File \"C:\\Users\\Ishika\\anaconda3\\lib\\threading.py\", line 932, in _bootstrap_inner\n",
      "Exception in thread Thread-39:\n",
      "Traceback (most recent call last):\n",
      "  File \"C:\\Users\\Ishika\\anaconda3\\lib\\threading.py\", line 932, in _bootstrap_inner\n",
      "    self.run()\n",
      "  File \"C:\\Users\\Ishika\\anaconda3\\lib\\threading.py\", line 870, in run\n",
      "    self.run()\n",
      "  File \"C:\\Users\\Ishika\\anaconda3\\lib\\threading.py\", line 870, in run\n",
      "    self._target(*self._args, **self._kwargs)\n",
      "TypeError: 'Thread' object is not callable\n",
      "    self._target(*self._args, **self._kwargs)\n",
      "TypeError: 'Thread' object is not callable\n",
      "Exception in thread Thread-40:\n",
      "Traceback (most recent call last):\n",
      "  File \"C:\\Users\\Ishika\\anaconda3\\lib\\threading.py\", line 932, in _bootstrap_inner\n",
      "Exception in thread Thread-41:\n",
      "Traceback (most recent call last):\n",
      "  File \"C:\\Users\\Ishika\\anaconda3\\lib\\threading.py\", line 932, in _bootstrap_inner\n",
      "        self.run()\n",
      "  File \"C:\\Users\\Ishika\\anaconda3\\lib\\threading.py\", line 870, in run\n",
      "self.run()\n",
      "  File \"C:\\Users\\Ishika\\anaconda3\\lib\\threading.py\", line 870, in run\n",
      "        self._target(*self._args, **self._kwargs)\n",
      "TypeError: 'Thread' object is not callable\n",
      "self._target(*self._args, **self._kwargs)\n",
      "TypeError: 'Thread' object is not callable\n",
      "Exception in thread Thread-42:\n",
      "Traceback (most recent call last):\n",
      "  File \"C:\\Users\\Ishika\\anaconda3\\lib\\threading.py\", line 932, in _bootstrap_inner\n",
      "Exception in thread Thread-43:\n",
      "Traceback (most recent call last):\n",
      "  File \"C:\\Users\\Ishika\\anaconda3\\lib\\threading.py\", line 932, in _bootstrap_inner\n",
      "        self.run()\n",
      "  File \"C:\\Users\\Ishika\\anaconda3\\lib\\threading.py\", line 870, in run\n",
      "self.run()\n",
      "  File \"C:\\Users\\Ishika\\anaconda3\\lib\\threading.py\", line 870, in run\n",
      "    self._target(*self._args, **self._kwargs)\n",
      "TypeError: 'Thread' object is not callable\n",
      "    self._target(*self._args, **self._kwargs)\n",
      "TypeError: 'Thread' object is not callable\n",
      "Exception in thread Thread-44:\n",
      "Traceback (most recent call last):\n",
      "  File \"C:\\Users\\Ishika\\anaconda3\\lib\\threading.py\", line 932, in _bootstrap_inner\n",
      "Exception in thread Thread-45:\n",
      "Traceback (most recent call last):\n",
      "  File \"C:\\Users\\Ishika\\anaconda3\\lib\\threading.py\", line 932, in _bootstrap_inner\n",
      "    self.run()\n",
      "  File \"C:\\Users\\Ishika\\anaconda3\\lib\\threading.py\", line 870, in run\n",
      "    self.run()\n",
      "  File \"C:\\Users\\Ishika\\anaconda3\\lib\\threading.py\", line 870, in run\n",
      "    self._target(*self._args, **self._kwargs)\n",
      "TypeError: 'Thread' object is not callable\n",
      "    self._target(*self._args, **self._kwargs)\n",
      "TypeError: 'Thread' object is not callable\n",
      "Exception in thread Thread-46:\n",
      "Traceback (most recent call last):\n",
      "  File \"C:\\Users\\Ishika\\anaconda3\\lib\\threading.py\", line 932, in _bootstrap_inner\n",
      "Exception in thread Thread-47:\n",
      "Traceback (most recent call last):\n",
      "  File \"C:\\Users\\Ishika\\anaconda3\\lib\\threading.py\", line 932, in _bootstrap_inner\n",
      "    self.run()\n",
      "  File \"C:\\Users\\Ishika\\anaconda3\\lib\\threading.py\", line 870, in run\n",
      "    self.run()\n",
      "  File \"C:\\Users\\Ishika\\anaconda3\\lib\\threading.py\", line 870, in run\n",
      "        self._target(*self._args, **self._kwargs)\n",
      "TypeError: 'Thread' object is not callable\n",
      "self._target(*self._args, **self._kwargs)\n",
      "TypeError: 'Thread' object is not callable\n",
      "Exception in thread Thread-48:\n",
      "Traceback (most recent call last):\n",
      "  File \"C:\\Users\\Ishika\\anaconda3\\lib\\threading.py\", line 932, in _bootstrap_inner\n",
      "Exception in thread Thread-49:\n",
      "Traceback (most recent call last):\n",
      "  File \"C:\\Users\\Ishika\\anaconda3\\lib\\threading.py\", line 932, in _bootstrap_inner\n",
      "    self.run()\n",
      "  File \"C:\\Users\\Ishika\\anaconda3\\lib\\threading.py\", line 870, in run\n",
      "    self.run()\n",
      "  File \"C:\\Users\\Ishika\\anaconda3\\lib\\threading.py\", line 870, in run\n",
      "        self._target(*self._args, **self._kwargs)self._target(*self._args, **self._kwargs)\n",
      "TypeError: 'Thread' object is not callable\n",
      "\n",
      "TypeError: 'Thread' object is not callable\n",
      "Exception in thread Thread-50:\n",
      "Traceback (most recent call last):\n",
      "  File \"C:\\Users\\Ishika\\anaconda3\\lib\\threading.py\", line 932, in _bootstrap_inner\n",
      "Exception in thread Thread-51:\n",
      "Traceback (most recent call last):\n",
      "  File \"C:\\Users\\Ishika\\anaconda3\\lib\\threading.py\", line 932, in _bootstrap_inner\n",
      "    self.run()\n",
      "  File \"C:\\Users\\Ishika\\anaconda3\\lib\\threading.py\", line 870, in run\n",
      "    self.run()\n",
      "  File \"C:\\Users\\Ishika\\anaconda3\\lib\\threading.py\", line 870, in run\n",
      "        self._target(*self._args, **self._kwargs)\n",
      "TypeError: 'Thread' object is not callable\n",
      "self._target(*self._args, **self._kwargs)\n",
      "TypeError: 'Thread' object is not callable\n",
      "Exception in thread Thread-52:\n",
      "Traceback (most recent call last):\n",
      "  File \"C:\\Users\\Ishika\\anaconda3\\lib\\threading.py\", line 932, in _bootstrap_inner\n",
      "Exception in thread Thread-53:\n",
      "Traceback (most recent call last):\n",
      "  File \"C:\\Users\\Ishika\\anaconda3\\lib\\threading.py\", line 932, in _bootstrap_inner\n",
      "    self.run()\n",
      "  File \"C:\\Users\\Ishika\\anaconda3\\lib\\threading.py\", line 870, in run\n",
      "    self.run()\n",
      "  File \"C:\\Users\\Ishika\\anaconda3\\lib\\threading.py\", line 870, in run\n",
      "    self._target(*self._args, **self._kwargs)\n",
      "TypeError: 'Thread' object is not callable\n",
      "    self._target(*self._args, **self._kwargs)\n",
      "TypeError: 'Thread' object is not callable\n",
      "Exception in thread Thread-54:\n",
      "Traceback (most recent call last):\n",
      "  File \"C:\\Users\\Ishika\\anaconda3\\lib\\threading.py\", line 932, in _bootstrap_inner\n",
      "Exception in thread Thread-55:\n",
      "Traceback (most recent call last):\n",
      "  File \"C:\\Users\\Ishika\\anaconda3\\lib\\threading.py\", line 932, in _bootstrap_inner\n",
      "    self.run()\n",
      "  File \"C:\\Users\\Ishika\\anaconda3\\lib\\threading.py\", line 870, in run\n",
      "    self.run()\n",
      "  File \"C:\\Users\\Ishika\\anaconda3\\lib\\threading.py\", line 870, in run\n",
      "    self._target(*self._args, **self._kwargs)\n",
      "TypeError: 'Thread' object is not callable\n",
      "    self._target(*self._args, **self._kwargs)\n",
      "TypeError: 'Thread' object is not callable\n",
      "Exception in thread Thread-56:\n",
      "Traceback (most recent call last):\n",
      "  File \"C:\\Users\\Ishika\\anaconda3\\lib\\threading.py\", line 932, in _bootstrap_inner\n",
      "Exception in thread Thread-57:\n",
      "Traceback (most recent call last):\n",
      "  File \"C:\\Users\\Ishika\\anaconda3\\lib\\threading.py\", line 932, in _bootstrap_inner\n",
      "    self.run()\n",
      "  File \"C:\\Users\\Ishika\\anaconda3\\lib\\threading.py\", line 870, in run\n",
      "    self.run()\n",
      "  File \"C:\\Users\\Ishika\\anaconda3\\lib\\threading.py\", line 870, in run\n",
      "        self._target(*self._args, **self._kwargs)\n",
      "TypeError: 'Thread' object is not callable\n",
      "self._target(*self._args, **self._kwargs)\n",
      "TypeError: 'Thread' object is not callable\n",
      "Exception in thread Thread-58:\n",
      "Traceback (most recent call last):\n",
      "  File \"C:\\Users\\Ishika\\anaconda3\\lib\\threading.py\", line 932, in _bootstrap_inner\n",
      "Exception in thread Thread-59:\n",
      "Traceback (most recent call last):\n",
      "  File \"C:\\Users\\Ishika\\anaconda3\\lib\\threading.py\", line 932, in _bootstrap_inner\n",
      "    self.run()\n",
      "  File \"C:\\Users\\Ishika\\anaconda3\\lib\\threading.py\", line 870, in run\n",
      "    self.run()\n",
      "  File \"C:\\Users\\Ishika\\anaconda3\\lib\\threading.py\", line 870, in run\n",
      "    self._target(*self._args, **self._kwargs)\n",
      "TypeError: 'Thread' object is not callable\n",
      "    self._target(*self._args, **self._kwargs)\n",
      "TypeError: 'Thread' object is not callable\n",
      "Exception in thread Thread-60:\n",
      "Traceback (most recent call last):\n",
      "  File \"C:\\Users\\Ishika\\anaconda3\\lib\\threading.py\", line 932, in _bootstrap_inner\n",
      "Exception in thread Thread-61:\n",
      "Traceback (most recent call last):\n",
      "  File \"C:\\Users\\Ishika\\anaconda3\\lib\\threading.py\", line 932, in _bootstrap_inner\n",
      "    self.run()\n",
      "  File \"C:\\Users\\Ishika\\anaconda3\\lib\\threading.py\", line 870, in run\n",
      "    self.run()\n",
      "  File \"C:\\Users\\Ishika\\anaconda3\\lib\\threading.py\", line 870, in run\n",
      "    self._target(*self._args, **self._kwargs)\n",
      "TypeError: 'Thread' object is not callable\n",
      "    self._target(*self._args, **self._kwargs)\n",
      "TypeError: 'Thread' object is not callable\n",
      "Exception in thread Thread-62:\n",
      "Traceback (most recent call last):\n",
      "  File \"C:\\Users\\Ishika\\anaconda3\\lib\\threading.py\", line 932, in _bootstrap_inner\n",
      "Exception in thread Thread-63:\n",
      "Traceback (most recent call last):\n",
      "  File \"C:\\Users\\Ishika\\anaconda3\\lib\\threading.py\", line 932, in _bootstrap_inner\n",
      "    self.run()\n",
      "  File \"C:\\Users\\Ishika\\anaconda3\\lib\\threading.py\", line 870, in run\n",
      "    self.run()\n",
      "  File \"C:\\Users\\Ishika\\anaconda3\\lib\\threading.py\", line 870, in run\n"
     ]
    },
    {
     "name": "stderr",
     "output_type": "stream",
     "text": [
      "    self._target(*self._args, **self._kwargs)\n",
      "TypeError: 'Thread' object is not callable\n",
      "    self._target(*self._args, **self._kwargs)\n",
      "TypeError: 'Thread' object is not callable\n",
      "Exception in thread Thread-64:\n",
      "Traceback (most recent call last):\n",
      "  File \"C:\\Users\\Ishika\\anaconda3\\lib\\threading.py\", line 932, in _bootstrap_inner\n",
      "Exception in thread Thread-65:\n",
      "Traceback (most recent call last):\n",
      "  File \"C:\\Users\\Ishika\\anaconda3\\lib\\threading.py\", line 932, in _bootstrap_inner\n",
      "    self.run()\n",
      "  File \"C:\\Users\\Ishika\\anaconda3\\lib\\threading.py\", line 870, in run\n",
      "    self.run()\n",
      "  File \"C:\\Users\\Ishika\\anaconda3\\lib\\threading.py\", line 870, in run\n",
      "        self._target(*self._args, **self._kwargs)\n",
      "TypeError: 'Thread' object is not callable\n",
      "self._target(*self._args, **self._kwargs)\n",
      "TypeError: 'Thread' object is not callable\n",
      "Exception in thread Thread-66:\n",
      "Traceback (most recent call last):\n",
      "  File \"C:\\Users\\Ishika\\anaconda3\\lib\\threading.py\", line 932, in _bootstrap_inner\n",
      "Exception in thread Thread-67:\n",
      "Traceback (most recent call last):\n",
      "  File \"C:\\Users\\Ishika\\anaconda3\\lib\\threading.py\", line 932, in _bootstrap_inner\n",
      "        self.run()\n",
      "  File \"C:\\Users\\Ishika\\anaconda3\\lib\\threading.py\", line 870, in run\n",
      "self.run()\n",
      "  File \"C:\\Users\\Ishika\\anaconda3\\lib\\threading.py\", line 870, in run\n",
      "        self._target(*self._args, **self._kwargs)\n",
      "TypeError: 'Thread' object is not callable\n",
      "self._target(*self._args, **self._kwargs)\n",
      "TypeError: 'Thread' object is not callable\n",
      "Exception in thread Thread-68:\n",
      "Traceback (most recent call last):\n",
      "  File \"C:\\Users\\Ishika\\anaconda3\\lib\\threading.py\", line 932, in _bootstrap_inner\n",
      "Exception in thread Thread-69:\n",
      "Traceback (most recent call last):\n",
      "  File \"C:\\Users\\Ishika\\anaconda3\\lib\\threading.py\", line 932, in _bootstrap_inner\n",
      "    self.run()\n",
      "  File \"C:\\Users\\Ishika\\anaconda3\\lib\\threading.py\", line 870, in run\n",
      "    self.run()\n",
      "  File \"C:\\Users\\Ishika\\anaconda3\\lib\\threading.py\", line 870, in run\n",
      "    self._target(*self._args, **self._kwargs)\n",
      "TypeError: 'Thread' object is not callable\n",
      "    self._target(*self._args, **self._kwargs)\n",
      "TypeError: 'Thread' object is not callable\n",
      "Exception in thread Thread-70:\n",
      "Traceback (most recent call last):\n",
      "  File \"C:\\Users\\Ishika\\anaconda3\\lib\\threading.py\", line 932, in _bootstrap_inner\n",
      "Exception in thread Thread-71:\n",
      "Traceback (most recent call last):\n",
      "  File \"C:\\Users\\Ishika\\anaconda3\\lib\\threading.py\", line 932, in _bootstrap_inner\n",
      "    self.run()\n",
      "  File \"C:\\Users\\Ishika\\anaconda3\\lib\\threading.py\", line 870, in run\n",
      "    self.run()\n",
      "  File \"C:\\Users\\Ishika\\anaconda3\\lib\\threading.py\", line 870, in run\n",
      "    self._target(*self._args, **self._kwargs)\n",
      "TypeError: 'Thread' object is not callable\n",
      "    self._target(*self._args, **self._kwargs)\n",
      "TypeError: 'Thread' object is not callable\n",
      "Exception in thread Thread-72:\n",
      "Exception in thread Traceback (most recent call last):\n",
      "Thread-73:\n",
      "Traceback (most recent call last):\n",
      "  File \"C:\\Users\\Ishika\\anaconda3\\lib\\threading.py\", line 932, in _bootstrap_inner\n",
      "  File \"C:\\Users\\Ishika\\anaconda3\\lib\\threading.py\", line 932, in _bootstrap_inner\n",
      "        self.run()\n",
      "  File \"C:\\Users\\Ishika\\anaconda3\\lib\\threading.py\", line 870, in run\n",
      "self.run()\n",
      "  File \"C:\\Users\\Ishika\\anaconda3\\lib\\threading.py\", line 870, in run\n",
      "    self._target(*self._args, **self._kwargs)\n",
      "TypeError: 'Thread' object is not callable\n",
      "    self._target(*self._args, **self._kwargs)\n",
      "TypeError: 'Thread' object is not callable\n",
      "Exception in thread Thread-74:\n",
      "Traceback (most recent call last):\n",
      "  File \"C:\\Users\\Ishika\\anaconda3\\lib\\threading.py\", line 932, in _bootstrap_inner\n",
      "Exception in thread Thread-75:\n",
      "Traceback (most recent call last):\n",
      "  File \"C:\\Users\\Ishika\\anaconda3\\lib\\threading.py\", line 932, in _bootstrap_inner\n",
      "    self.run()\n",
      "  File \"C:\\Users\\Ishika\\anaconda3\\lib\\threading.py\", line 870, in run\n",
      "    self.run()\n",
      "  File \"C:\\Users\\Ishika\\anaconda3\\lib\\threading.py\", line 870, in run\n",
      "        self._target(*self._args, **self._kwargs)\n",
      "TypeError: 'Thread' object is not callable\n",
      "self._target(*self._args, **self._kwargs)\n",
      "TypeError: 'Thread' object is not callable\n",
      "Exception in thread Thread-76:\n",
      "Traceback (most recent call last):\n",
      "  File \"C:\\Users\\Ishika\\anaconda3\\lib\\threading.py\", line 932, in _bootstrap_inner\n",
      "Exception in thread Thread-77:\n",
      "Traceback (most recent call last):\n",
      "  File \"C:\\Users\\Ishika\\anaconda3\\lib\\threading.py\", line 932, in _bootstrap_inner\n",
      "    self.run()\n",
      "  File \"C:\\Users\\Ishika\\anaconda3\\lib\\threading.py\", line 870, in run\n",
      "    self.run()\n",
      "  File \"C:\\Users\\Ishika\\anaconda3\\lib\\threading.py\", line 870, in run\n",
      "        self._target(*self._args, **self._kwargs)\n",
      "TypeError: 'Thread' object is not callable\n",
      "self._target(*self._args, **self._kwargs)\n",
      "TypeError: 'Thread' object is not callable\n",
      "Exception in thread Thread-78:\n",
      "Traceback (most recent call last):\n",
      "  File \"C:\\Users\\Ishika\\anaconda3\\lib\\threading.py\", line 932, in _bootstrap_inner\n",
      "Exception in thread Thread-79:\n",
      "Traceback (most recent call last):\n",
      "  File \"C:\\Users\\Ishika\\anaconda3\\lib\\threading.py\", line 932, in _bootstrap_inner\n",
      "    self.run()\n",
      "  File \"C:\\Users\\Ishika\\anaconda3\\lib\\threading.py\", line 870, in run\n",
      "    self.run()\n",
      "  File \"C:\\Users\\Ishika\\anaconda3\\lib\\threading.py\", line 870, in run\n",
      "    self._target(*self._args, **self._kwargs)\n",
      "    TypeError: 'Thread' object is not callable\n",
      "self._target(*self._args, **self._kwargs)\n",
      "TypeError: 'Thread' object is not callable\n",
      "Exception in thread Thread-80:\n",
      "Traceback (most recent call last):\n",
      "  File \"C:\\Users\\Ishika\\anaconda3\\lib\\threading.py\", line 932, in _bootstrap_inner\n",
      "Exception in thread Thread-81:\n",
      "Traceback (most recent call last):\n",
      "  File \"C:\\Users\\Ishika\\anaconda3\\lib\\threading.py\", line 932, in _bootstrap_inner\n",
      "        self.run()\n",
      "  File \"C:\\Users\\Ishika\\anaconda3\\lib\\threading.py\", line 870, in run\n",
      "self.run()\n",
      "  File \"C:\\Users\\Ishika\\anaconda3\\lib\\threading.py\", line 870, in run\n",
      "        self._target(*self._args, **self._kwargs)\n",
      "TypeError: self._target(*self._args, **self._kwargs)\n",
      "'Thread' object is not callable\n",
      "TypeError: 'Thread' object is not callable\n",
      "Exception in thread Thread-82:\n",
      "Traceback (most recent call last):\n",
      "  File \"C:\\Users\\Ishika\\anaconda3\\lib\\threading.py\", line 932, in _bootstrap_inner\n",
      "Exception in thread Thread-83:\n",
      "Traceback (most recent call last):\n",
      "  File \"C:\\Users\\Ishika\\anaconda3\\lib\\threading.py\", line 932, in _bootstrap_inner\n",
      "    self.run()\n",
      "  File \"C:\\Users\\Ishika\\anaconda3\\lib\\threading.py\", line 870, in run\n",
      "    self.run()\n",
      "  File \"C:\\Users\\Ishika\\anaconda3\\lib\\threading.py\", line 870, in run\n",
      "    self._target(*self._args, **self._kwargs)\n",
      "TypeError: 'Thread' object is not callable\n",
      "    self._target(*self._args, **self._kwargs)\n",
      "TypeError: 'Thread' object is not callable\n",
      "Exception in thread Thread-84:\n",
      "Traceback (most recent call last):\n",
      "  File \"C:\\Users\\Ishika\\anaconda3\\lib\\threading.py\", line 932, in _bootstrap_inner\n",
      "Exception in thread Thread-85:\n",
      "Traceback (most recent call last):\n",
      "  File \"C:\\Users\\Ishika\\anaconda3\\lib\\threading.py\", line 932, in _bootstrap_inner\n",
      "        self.run()self.run()\n",
      "  File \"C:\\Users\\Ishika\\anaconda3\\lib\\threading.py\", line 870, in run\n",
      "\n",
      "  File \"C:\\Users\\Ishika\\anaconda3\\lib\\threading.py\", line 870, in run\n",
      "        self._target(*self._args, **self._kwargs)\n",
      "TypeError: 'Thread' object is not callable\n",
      "self._target(*self._args, **self._kwargs)\n",
      "TypeError: 'Thread' object is not callable\n",
      "Exception in thread Thread-86:\n",
      "Traceback (most recent call last):\n",
      "  File \"C:\\Users\\Ishika\\anaconda3\\lib\\threading.py\", line 932, in _bootstrap_inner\n",
      "Exception in thread Thread-87:\n",
      "Traceback (most recent call last):\n",
      "  File \"C:\\Users\\Ishika\\anaconda3\\lib\\threading.py\", line 932, in _bootstrap_inner\n",
      "        self.run()\n",
      "  File \"C:\\Users\\Ishika\\anaconda3\\lib\\threading.py\", line 870, in run\n",
      "self.run()\n",
      "  File \"C:\\Users\\Ishika\\anaconda3\\lib\\threading.py\", line 870, in run\n",
      "        self._target(*self._args, **self._kwargs)\n",
      "TypeError: 'Thread' object is not callable\n",
      "self._target(*self._args, **self._kwargs)\n",
      "TypeError: 'Thread' object is not callable\n",
      "Exception in thread Thread-88:\n",
      "Traceback (most recent call last):\n",
      "  File \"C:\\Users\\Ishika\\anaconda3\\lib\\threading.py\", line 932, in _bootstrap_inner\n",
      "Exception in thread Thread-89:\n",
      "Traceback (most recent call last):\n",
      "  File \"C:\\Users\\Ishika\\anaconda3\\lib\\threading.py\", line 932, in _bootstrap_inner\n",
      "        self.run()\n",
      "  File \"C:\\Users\\Ishika\\anaconda3\\lib\\threading.py\", line 870, in run\n",
      "self.run()\n",
      "  File \"C:\\Users\\Ishika\\anaconda3\\lib\\threading.py\", line 870, in run\n",
      "    self._target(*self._args, **self._kwargs)\n",
      "TypeError: 'Thread' object is not callable\n"
     ]
    },
    {
     "name": "stderr",
     "output_type": "stream",
     "text": [
      "    self._target(*self._args, **self._kwargs)\n",
      "TypeError: 'Thread' object is not callable\n",
      "Exception in thread Thread-90:\n",
      "Traceback (most recent call last):\n",
      "  File \"C:\\Users\\Ishika\\anaconda3\\lib\\threading.py\", line 932, in _bootstrap_inner\n",
      "Exception in thread Thread-91:\n",
      "Traceback (most recent call last):\n",
      "  File \"C:\\Users\\Ishika\\anaconda3\\lib\\threading.py\", line 932, in _bootstrap_inner\n",
      "    self.run()\n",
      "  File \"C:\\Users\\Ishika\\anaconda3\\lib\\threading.py\", line 870, in run\n",
      "    self.run()\n",
      "  File \"C:\\Users\\Ishika\\anaconda3\\lib\\threading.py\", line 870, in run\n",
      "        self._target(*self._args, **self._kwargs)\n",
      "TypeError: 'Thread' object is not callable\n",
      "self._target(*self._args, **self._kwargs)\n",
      "TypeError: 'Thread' object is not callable\n",
      "Exception in thread Thread-92:\n",
      "Traceback (most recent call last):\n",
      "  File \"C:\\Users\\Ishika\\anaconda3\\lib\\threading.py\", line 932, in _bootstrap_inner\n",
      "Exception in thread Thread-93:\n",
      "Traceback (most recent call last):\n",
      "  File \"C:\\Users\\Ishika\\anaconda3\\lib\\threading.py\", line 932, in _bootstrap_inner\n",
      "    self.run()\n",
      "  File \"C:\\Users\\Ishika\\anaconda3\\lib\\threading.py\", line 870, in run\n",
      "    self.run()\n",
      "  File \"C:\\Users\\Ishika\\anaconda3\\lib\\threading.py\", line 870, in run\n",
      "    self._target(*self._args, **self._kwargs)\n",
      "TypeError: 'Thread' object is not callable\n",
      "    self._target(*self._args, **self._kwargs)\n",
      "TypeError: 'Thread' object is not callable\n",
      "Exception in thread Thread-94:\n",
      "Traceback (most recent call last):\n",
      "Exception in thread   File \"C:\\Users\\Ishika\\anaconda3\\lib\\threading.py\", line 932, in _bootstrap_inner\n",
      "Thread-95:\n",
      "Traceback (most recent call last):\n",
      "  File \"C:\\Users\\Ishika\\anaconda3\\lib\\threading.py\", line 932, in _bootstrap_inner\n",
      "        self.run()\n",
      "  File \"C:\\Users\\Ishika\\anaconda3\\lib\\threading.py\", line 870, in run\n",
      "self.run()\n",
      "  File \"C:\\Users\\Ishika\\anaconda3\\lib\\threading.py\", line 870, in run\n",
      "        self._target(*self._args, **self._kwargs)self._target(*self._args, **self._kwargs)\n",
      "TypeError: 'Thread' object is not callable\n",
      "\n",
      "TypeError: 'Thread' object is not callable\n",
      "Exception in thread Exception in thread Thread-96Thread-97:\n",
      "Traceback (most recent call last):\n",
      "  File \"C:\\Users\\Ishika\\anaconda3\\lib\\threading.py\", line 932, in _bootstrap_inner\n",
      ":\n",
      "Traceback (most recent call last):\n",
      "  File \"C:\\Users\\Ishika\\anaconda3\\lib\\threading.py\", line 932, in _bootstrap_inner\n",
      "    self.run()\n",
      "  File \"C:\\Users\\Ishika\\anaconda3\\lib\\threading.py\", line 870, in run\n",
      "    self.run()\n",
      "  File \"C:\\Users\\Ishika\\anaconda3\\lib\\threading.py\", line 870, in run\n",
      "    self._target(*self._args, **self._kwargs)\n",
      "TypeError:     self._target(*self._args, **self._kwargs)\n",
      "TypeError: 'Thread' object is not callable\n",
      "'Thread' object is not callable\n",
      "Exception in thread Thread-98:\n",
      "Traceback (most recent call last):\n",
      "  File \"C:\\Users\\Ishika\\anaconda3\\lib\\threading.py\", line 932, in _bootstrap_inner\n",
      "Exception in thread Thread-99:\n",
      "Traceback (most recent call last):\n",
      "  File \"C:\\Users\\Ishika\\anaconda3\\lib\\threading.py\", line 932, in _bootstrap_inner\n",
      "        self.run()\n",
      "  File \"C:\\Users\\Ishika\\anaconda3\\lib\\threading.py\", line 870, in run\n",
      "self.run()\n",
      "  File \"C:\\Users\\Ishika\\anaconda3\\lib\\threading.py\", line 870, in run\n",
      "        self._target(*self._args, **self._kwargs)\n",
      "TypeError: 'Thread' object is not callable\n",
      "self._target(*self._args, **self._kwargs)\n",
      "TypeError: 'Thread' object is not callable\n",
      "Exception in thread Thread-100:\n",
      "Traceback (most recent call last):\n",
      "  File \"C:\\Users\\Ishika\\anaconda3\\lib\\threading.py\", line 932, in _bootstrap_inner\n",
      "Exception in thread Thread-101:\n",
      "Traceback (most recent call last):\n",
      "  File \"C:\\Users\\Ishika\\anaconda3\\lib\\threading.py\", line 932, in _bootstrap_inner\n",
      "    self.run()\n",
      "  File \"C:\\Users\\Ishika\\anaconda3\\lib\\threading.py\", line 870, in run\n",
      "    self.run()\n",
      "  File \"C:\\Users\\Ishika\\anaconda3\\lib\\threading.py\", line 870, in run\n",
      "    self._target(*self._args, **self._kwargs)\n",
      "TypeError: 'Thread' object is not callable\n",
      "    self._target(*self._args, **self._kwargs)\n",
      "TypeError: 'Thread' object is not callable\n",
      "Exception in thread Thread-102:\n",
      "Traceback (most recent call last):\n",
      "  File \"C:\\Users\\Ishika\\anaconda3\\lib\\threading.py\", line 932, in _bootstrap_inner\n",
      "Exception in thread Thread-103:\n",
      "Traceback (most recent call last):\n",
      "  File \"C:\\Users\\Ishika\\anaconda3\\lib\\threading.py\", line 932, in _bootstrap_inner\n",
      "    self.run()\n",
      "  File \"C:\\Users\\Ishika\\anaconda3\\lib\\threading.py\", line 870, in run\n",
      "    self.run()\n",
      "  File \"C:\\Users\\Ishika\\anaconda3\\lib\\threading.py\", line 870, in run\n",
      "    self._target(*self._args, **self._kwargs)\n",
      "TypeError: 'Thread' object is not callable\n",
      "    self._target(*self._args, **self._kwargs)\n",
      "TypeError: 'Thread' object is not callable\n",
      "Exception in thread Thread-104:\n",
      "Traceback (most recent call last):\n",
      "  File \"C:\\Users\\Ishika\\anaconda3\\lib\\threading.py\", line 932, in _bootstrap_inner\n",
      "Exception in thread Thread-105:\n",
      "Traceback (most recent call last):\n",
      "  File \"C:\\Users\\Ishika\\anaconda3\\lib\\threading.py\", line 932, in _bootstrap_inner\n",
      "    self.run()\n",
      "  File \"C:\\Users\\Ishika\\anaconda3\\lib\\threading.py\", line 870, in run\n",
      "    self.run()\n",
      "  File \"C:\\Users\\Ishika\\anaconda3\\lib\\threading.py\", line 870, in run\n",
      "    self._target(*self._args, **self._kwargs)\n",
      "TypeError: 'Thread' object is not callable\n",
      "    self._target(*self._args, **self._kwargs)\n",
      "TypeError: 'Thread' object is not callable\n",
      "Exception in thread Thread-106:\n",
      "Traceback (most recent call last):\n",
      "  File \"C:\\Users\\Ishika\\anaconda3\\lib\\threading.py\", line 932, in _bootstrap_inner\n",
      "Exception in thread Thread-107:\n",
      "Traceback (most recent call last):\n",
      "  File \"C:\\Users\\Ishika\\anaconda3\\lib\\threading.py\", line 932, in _bootstrap_inner\n",
      "        self.run()\n",
      "  File \"C:\\Users\\Ishika\\anaconda3\\lib\\threading.py\", line 870, in run\n",
      "self.run()\n",
      "  File \"C:\\Users\\Ishika\\anaconda3\\lib\\threading.py\", line 870, in run\n",
      "        self._target(*self._args, **self._kwargs)\n",
      "TypeError: 'Thread' object is not callable\n",
      "self._target(*self._args, **self._kwargs)\n",
      "TypeError: 'Thread' object is not callable\n",
      "Exception in thread Thread-108:\n",
      "Traceback (most recent call last):\n",
      "  File \"C:\\Users\\Ishika\\anaconda3\\lib\\threading.py\", line 932, in _bootstrap_inner\n",
      "Exception in thread Thread-109:\n",
      "Traceback (most recent call last):\n",
      "  File \"C:\\Users\\Ishika\\anaconda3\\lib\\threading.py\", line 932, in _bootstrap_inner\n",
      "    self.run()\n",
      "  File \"C:\\Users\\Ishika\\anaconda3\\lib\\threading.py\", line 870, in run\n",
      "    self.run()\n",
      "  File \"C:\\Users\\Ishika\\anaconda3\\lib\\threading.py\", line 870, in run\n",
      "    self._target(*self._args, **self._kwargs)\n",
      "TypeError: 'Thread' object is not callable\n",
      "    self._target(*self._args, **self._kwargs)\n",
      "TypeError: 'Thread' object is not callable\n",
      "Exception in thread Thread-110:\n",
      "Traceback (most recent call last):\n",
      "  File \"C:\\Users\\Ishika\\anaconda3\\lib\\threading.py\", line 932, in _bootstrap_inner\n",
      "Exception in thread Thread-111:\n",
      "Traceback (most recent call last):\n",
      "  File \"C:\\Users\\Ishika\\anaconda3\\lib\\threading.py\", line 932, in _bootstrap_inner\n",
      "    self.run()\n",
      "  File \"C:\\Users\\Ishika\\anaconda3\\lib\\threading.py\", line 870, in run\n",
      "    self.run()\n",
      "  File \"C:\\Users\\Ishika\\anaconda3\\lib\\threading.py\", line 870, in run\n",
      "    self._target(*self._args, **self._kwargs)\n",
      "TypeError: 'Thread' object is not callable\n",
      "    self._target(*self._args, **self._kwargs)\n",
      "TypeError: 'Thread' object is not callable\n",
      "Exception in thread Exception in thread Thread-112Thread-113:\n",
      "Traceback (most recent call last):\n",
      "  File \"C:\\Users\\Ishika\\anaconda3\\lib\\threading.py\", line 932, in _bootstrap_inner\n",
      ":\n",
      "Traceback (most recent call last):\n",
      "  File \"C:\\Users\\Ishika\\anaconda3\\lib\\threading.py\", line 932, in _bootstrap_inner\n",
      "    self.run()\n",
      "  File \"C:\\Users\\Ishika\\anaconda3\\lib\\threading.py\", line 870, in run\n",
      "    self.run()\n",
      "  File \"C:\\Users\\Ishika\\anaconda3\\lib\\threading.py\", line 870, in run\n",
      "    self._target(*self._args, **self._kwargs)\n",
      "TypeError: 'Thread' object is not callable\n",
      "    self._target(*self._args, **self._kwargs)\n",
      "TypeError: 'Thread' object is not callable\n",
      "Exception in thread Thread-114:\n",
      "Traceback (most recent call last):\n",
      "  File \"C:\\Users\\Ishika\\anaconda3\\lib\\threading.py\", line 932, in _bootstrap_inner\n",
      "Exception in thread Thread-115:\n",
      "Traceback (most recent call last):\n",
      "  File \"C:\\Users\\Ishika\\anaconda3\\lib\\threading.py\", line 932, in _bootstrap_inner\n",
      "    self.run()\n",
      "  File \"C:\\Users\\Ishika\\anaconda3\\lib\\threading.py\", line 870, in run\n",
      "    self.run()\n",
      "  File \"C:\\Users\\Ishika\\anaconda3\\lib\\threading.py\", line 870, in run\n",
      "    self._target(*self._args, **self._kwargs)\n",
      "TypeError: 'Thread' object is not callable\n"
     ]
    },
    {
     "name": "stderr",
     "output_type": "stream",
     "text": [
      "    self._target(*self._args, **self._kwargs)\n",
      "TypeError: 'Thread' object is not callable\n",
      "Exception in thread Thread-116:\n",
      "Traceback (most recent call last):\n",
      "  File \"C:\\Users\\Ishika\\anaconda3\\lib\\threading.py\", line 932, in _bootstrap_inner\n",
      "Exception in thread Thread-117:\n",
      "Traceback (most recent call last):\n",
      "  File \"C:\\Users\\Ishika\\anaconda3\\lib\\threading.py\", line 932, in _bootstrap_inner\n",
      "    self.run()\n",
      "  File \"C:\\Users\\Ishika\\anaconda3\\lib\\threading.py\", line 870, in run\n",
      "    self.run()\n",
      "  File \"C:\\Users\\Ishika\\anaconda3\\lib\\threading.py\", line 870, in run\n",
      "        self._target(*self._args, **self._kwargs)\n",
      "TypeError: 'Thread' object is not callable\n",
      "self._target(*self._args, **self._kwargs)\n",
      "TypeError: 'Thread' object is not callable\n",
      "Exception in thread Thread-118:\n",
      "Traceback (most recent call last):\n",
      "  File \"C:\\Users\\Ishika\\anaconda3\\lib\\threading.py\", line 932, in _bootstrap_inner\n",
      "Exception in thread Thread-119:\n",
      "Traceback (most recent call last):\n",
      "  File \"C:\\Users\\Ishika\\anaconda3\\lib\\threading.py\", line 932, in _bootstrap_inner\n",
      "    self.run()\n",
      "  File \"C:\\Users\\Ishika\\anaconda3\\lib\\threading.py\", line 870, in run\n",
      "    self.run()\n",
      "  File \"C:\\Users\\Ishika\\anaconda3\\lib\\threading.py\", line 870, in run\n",
      "    self._target(*self._args, **self._kwargs)\n",
      "TypeError: 'Thread' object is not callable\n",
      "    self._target(*self._args, **self._kwargs)\n",
      "TypeError: 'Thread' object is not callable\n",
      "Exception in thread Thread-120:\n",
      "Traceback (most recent call last):\n",
      "  File \"C:\\Users\\Ishika\\anaconda3\\lib\\threading.py\", line 932, in _bootstrap_inner\n",
      "Exception in thread Thread-121:\n",
      "Traceback (most recent call last):\n",
      "  File \"C:\\Users\\Ishika\\anaconda3\\lib\\threading.py\", line 932, in _bootstrap_inner\n",
      "    self.run()\n",
      "  File \"C:\\Users\\Ishika\\anaconda3\\lib\\threading.py\", line 870, in run\n",
      "    self.run()\n",
      "  File \"C:\\Users\\Ishika\\anaconda3\\lib\\threading.py\", line 870, in run\n",
      "    self._target(*self._args, **self._kwargs)\n",
      "TypeError: 'Thread' object is not callable\n",
      "    self._target(*self._args, **self._kwargs)\n",
      "TypeError: 'Thread' object is not callable\n",
      "Exception in thread Thread-122:\n",
      "Traceback (most recent call last):\n",
      "  File \"C:\\Users\\Ishika\\anaconda3\\lib\\threading.py\", line 932, in _bootstrap_inner\n",
      "Exception in thread Thread-123:\n",
      "Traceback (most recent call last):\n",
      "  File \"C:\\Users\\Ishika\\anaconda3\\lib\\threading.py\", line 932, in _bootstrap_inner\n",
      "        self.run()\n",
      "  File \"C:\\Users\\Ishika\\anaconda3\\lib\\threading.py\", line 870, in run\n",
      "self.run()\n",
      "  File \"C:\\Users\\Ishika\\anaconda3\\lib\\threading.py\", line 870, in run\n",
      "    self._target(*self._args, **self._kwargs)\n",
      "TypeError: 'Thread' object is not callable\n",
      "    self._target(*self._args, **self._kwargs)\n",
      "TypeError: 'Thread' object is not callable\n",
      "Exception in thread Thread-124:\n",
      "Traceback (most recent call last):\n",
      "  File \"C:\\Users\\Ishika\\anaconda3\\lib\\threading.py\", line 932, in _bootstrap_inner\n",
      "Exception in thread Thread-125:\n",
      "Traceback (most recent call last):\n",
      "  File \"C:\\Users\\Ishika\\anaconda3\\lib\\threading.py\", line 932, in _bootstrap_inner\n",
      "    self.run()\n",
      "  File \"C:\\Users\\Ishika\\anaconda3\\lib\\threading.py\", line 870, in run\n",
      "    self.run()\n",
      "  File \"C:\\Users\\Ishika\\anaconda3\\lib\\threading.py\", line 870, in run\n",
      "    self._target(*self._args, **self._kwargs)\n",
      "TypeError: 'Thread' object is not callable\n",
      "    self._target(*self._args, **self._kwargs)\n",
      "TypeError: 'Thread' object is not callable\n",
      "Exception in thread Thread-126:\n",
      "Traceback (most recent call last):\n",
      "  File \"C:\\Users\\Ishika\\anaconda3\\lib\\threading.py\", line 932, in _bootstrap_inner\n",
      "Exception in thread Thread-127:\n",
      "Traceback (most recent call last):\n",
      "  File \"C:\\Users\\Ishika\\anaconda3\\lib\\threading.py\", line 932, in _bootstrap_inner\n",
      "    self.run()\n",
      "  File \"C:\\Users\\Ishika\\anaconda3\\lib\\threading.py\", line 870, in run\n",
      "    self.run()\n",
      "  File \"C:\\Users\\Ishika\\anaconda3\\lib\\threading.py\", line 870, in run\n",
      "    self._target(*self._args, **self._kwargs)\n",
      "TypeError: 'Thread' object is not callable\n",
      "    self._target(*self._args, **self._kwargs)\n",
      "TypeError: 'Thread' object is not callable\n",
      "Exception in thread Thread-128:\n",
      "Traceback (most recent call last):\n",
      "  File \"C:\\Users\\Ishika\\anaconda3\\lib\\threading.py\", line 932, in _bootstrap_inner\n",
      "Exception in thread Thread-129:\n",
      "Traceback (most recent call last):\n",
      "  File \"C:\\Users\\Ishika\\anaconda3\\lib\\threading.py\", line 932, in _bootstrap_inner\n",
      "    self.run()\n",
      "  File \"C:\\Users\\Ishika\\anaconda3\\lib\\threading.py\", line 870, in run\n",
      "    self.run()\n",
      "  File \"C:\\Users\\Ishika\\anaconda3\\lib\\threading.py\", line 870, in run\n",
      "    self._target(*self._args, **self._kwargs)\n",
      "TypeError: 'Thread' object is not callable\n",
      "    self._target(*self._args, **self._kwargs)\n",
      "TypeError: 'Thread' object is not callable\n",
      "Exception in thread Thread-130:\n",
      "Traceback (most recent call last):\n",
      "  File \"C:\\Users\\Ishika\\anaconda3\\lib\\threading.py\", line 932, in _bootstrap_inner\n",
      "Exception in thread Thread-131:\n",
      "Traceback (most recent call last):\n",
      "  File \"C:\\Users\\Ishika\\anaconda3\\lib\\threading.py\", line 932, in _bootstrap_inner\n",
      "        self.run()\n",
      "  File \"C:\\Users\\Ishika\\anaconda3\\lib\\threading.py\", line 870, in run\n",
      "self.run()\n",
      "  File \"C:\\Users\\Ishika\\anaconda3\\lib\\threading.py\", line 870, in run\n",
      "    self._target(*self._args, **self._kwargs)\n",
      "TypeError: 'Thread' object is not callable\n",
      "    self._target(*self._args, **self._kwargs)\n",
      "TypeError: 'Thread' object is not callable\n",
      "Exception in thread Thread-132:\n",
      "Traceback (most recent call last):\n",
      "  File \"C:\\Users\\Ishika\\anaconda3\\lib\\threading.py\", line 932, in _bootstrap_inner\n",
      "Exception in thread Thread-133:\n",
      "Traceback (most recent call last):\n",
      "  File \"C:\\Users\\Ishika\\anaconda3\\lib\\threading.py\", line 932, in _bootstrap_inner\n",
      "    self.run()\n",
      "  File \"C:\\Users\\Ishika\\anaconda3\\lib\\threading.py\", line 870, in run\n",
      "    self.run()\n",
      "  File \"C:\\Users\\Ishika\\anaconda3\\lib\\threading.py\", line 870, in run\n",
      "    self._target(*self._args, **self._kwargs)\n",
      "TypeError: 'Thread' object is not callable\n",
      "    self._target(*self._args, **self._kwargs)\n",
      "TypeError: 'Thread' object is not callable\n",
      "Exception in thread Thread-134:\n",
      "Traceback (most recent call last):\n",
      "  File \"C:\\Users\\Ishika\\anaconda3\\lib\\threading.py\", line 932, in _bootstrap_inner\n",
      "Exception in thread Thread-135:\n",
      "Traceback (most recent call last):\n",
      "  File \"C:\\Users\\Ishika\\anaconda3\\lib\\threading.py\", line 932, in _bootstrap_inner\n",
      "    self.run()\n",
      "  File \"C:\\Users\\Ishika\\anaconda3\\lib\\threading.py\", line 870, in run\n",
      "    self.run()\n",
      "  File \"C:\\Users\\Ishika\\anaconda3\\lib\\threading.py\", line 870, in run\n",
      "    self._target(*self._args, **self._kwargs)\n",
      "TypeError: 'Thread' object is not callable\n",
      "    self._target(*self._args, **self._kwargs)\n",
      "TypeError: 'Thread' object is not callable\n",
      "Exception in thread Thread-136:\n",
      "Traceback (most recent call last):\n",
      "  File \"C:\\Users\\Ishika\\anaconda3\\lib\\threading.py\", line 932, in _bootstrap_inner\n",
      "Exception in thread Thread-137:\n",
      "Traceback (most recent call last):\n",
      "  File \"C:\\Users\\Ishika\\anaconda3\\lib\\threading.py\", line 932, in _bootstrap_inner\n",
      "        self.run()\n",
      "  File \"C:\\Users\\Ishika\\anaconda3\\lib\\threading.py\", line 870, in run\n",
      "self.run()\n",
      "  File \"C:\\Users\\Ishika\\anaconda3\\lib\\threading.py\", line 870, in run\n",
      "        self._target(*self._args, **self._kwargs)\n",
      "TypeError: 'Thread' object is not callable\n",
      "self._target(*self._args, **self._kwargs)\n",
      "TypeError: 'Thread' object is not callable\n",
      "Exception in thread Thread-138:\n",
      "Traceback (most recent call last):\n",
      "  File \"C:\\Users\\Ishika\\anaconda3\\lib\\threading.py\", line 932, in _bootstrap_inner\n",
      "    self.run()\n",
      "  File \"C:\\Users\\Ishika\\anaconda3\\lib\\threading.py\", line 870, in run\n",
      "    self._target(*self._args, **self._kwargs)\n",
      "TypeError: 'Thread' object is not callable\n",
      "Exception in thread Thread-139:\n",
      "Traceback (most recent call last):\n",
      "  File \"C:\\Users\\Ishika\\anaconda3\\lib\\threading.py\", line 932, in _bootstrap_inner\n",
      "    self.run()\n",
      "  File \"C:\\Users\\Ishika\\anaconda3\\lib\\threading.py\", line 870, in run\n",
      "    self._target(*self._args, **self._kwargs)\n",
      "TypeError: 'Thread' object is not callable\n",
      "Exception in thread Exception in thread Thread-140:\n",
      "Traceback (most recent call last):\n",
      "  File \"C:\\Users\\Ishika\\anaconda3\\lib\\threading.py\", line 932, in _bootstrap_inner\n",
      "Thread-141:\n",
      "Traceback (most recent call last):\n",
      "  File \"C:\\Users\\Ishika\\anaconda3\\lib\\threading.py\", line 932, in _bootstrap_inner\n",
      "    self.run()\n",
      "  File \"C:\\Users\\Ishika\\anaconda3\\lib\\threading.py\", line 870, in run\n",
      "    self.run()\n",
      "  File \"C:\\Users\\Ishika\\anaconda3\\lib\\threading.py\", line 870, in run\n",
      "    self._target(*self._args, **self._kwargs)\n",
      "TypeError: 'Thread' object is not callable\n"
     ]
    },
    {
     "name": "stderr",
     "output_type": "stream",
     "text": [
      "    self._target(*self._args, **self._kwargs)\n",
      "TypeError: 'Thread' object is not callable\n",
      "Exception in thread Thread-142:\n",
      "Traceback (most recent call last):\n",
      "  File \"C:\\Users\\Ishika\\anaconda3\\lib\\threading.py\", line 932, in _bootstrap_inner\n",
      "Exception in thread Thread-143:\n",
      "Traceback (most recent call last):\n",
      "  File \"C:\\Users\\Ishika\\anaconda3\\lib\\threading.py\", line 932, in _bootstrap_inner\n",
      "    self.run()\n",
      "  File \"C:\\Users\\Ishika\\anaconda3\\lib\\threading.py\", line 870, in run\n",
      "    self.run()\n",
      "  File \"C:\\Users\\Ishika\\anaconda3\\lib\\threading.py\", line 870, in run\n",
      "    self._target(*self._args, **self._kwargs)\n",
      "TypeError: 'Thread' object is not callable\n",
      "    self._target(*self._args, **self._kwargs)\n",
      "TypeError: 'Thread' object is not callable\n",
      "Exception in thread Thread-144:\n",
      "Traceback (most recent call last):\n",
      "  File \"C:\\Users\\Ishika\\anaconda3\\lib\\threading.py\", line 932, in _bootstrap_inner\n",
      "Exception in thread Thread-145:\n",
      "Traceback (most recent call last):\n",
      "  File \"C:\\Users\\Ishika\\anaconda3\\lib\\threading.py\", line 932, in _bootstrap_inner\n",
      "    self.run()\n",
      "  File \"C:\\Users\\Ishika\\anaconda3\\lib\\threading.py\", line 870, in run\n",
      "    self.run()\n",
      "  File \"C:\\Users\\Ishika\\anaconda3\\lib\\threading.py\", line 870, in run\n",
      "    self._target(*self._args, **self._kwargs)\n",
      "TypeError: 'Thread' object is not callable\n",
      "    self._target(*self._args, **self._kwargs)\n",
      "TypeError: 'Thread' object is not callable\n",
      "Exception in thread Thread-146:\n",
      "Traceback (most recent call last):\n",
      "  File \"C:\\Users\\Ishika\\anaconda3\\lib\\threading.py\", line 932, in _bootstrap_inner\n",
      "Exception in thread Thread-147:\n",
      "Traceback (most recent call last):\n",
      "  File \"C:\\Users\\Ishika\\anaconda3\\lib\\threading.py\", line 932, in _bootstrap_inner\n",
      "    self.run()\n",
      "  File \"C:\\Users\\Ishika\\anaconda3\\lib\\threading.py\", line 870, in run\n",
      "    self.run()\n",
      "  File \"C:\\Users\\Ishika\\anaconda3\\lib\\threading.py\", line 870, in run\n",
      "    self._target(*self._args, **self._kwargs)\n",
      "TypeError: 'Thread' object is not callable\n",
      "    self._target(*self._args, **self._kwargs)\n",
      "TypeError: 'Thread' object is not callable\n",
      "Exception in thread Thread-148:\n",
      "Traceback (most recent call last):\n",
      "  File \"C:\\Users\\Ishika\\anaconda3\\lib\\threading.py\", line 932, in _bootstrap_inner\n",
      "Exception in thread Thread-149:\n",
      "Traceback (most recent call last):\n",
      "  File \"C:\\Users\\Ishika\\anaconda3\\lib\\threading.py\", line 932, in _bootstrap_inner\n",
      "    self.run()\n",
      "  File \"C:\\Users\\Ishika\\anaconda3\\lib\\threading.py\", line 870, in run\n",
      "    self.run()\n",
      "  File \"C:\\Users\\Ishika\\anaconda3\\lib\\threading.py\", line 870, in run\n",
      "    self._target(*self._args, **self._kwargs)\n",
      "TypeError: 'Thread' object is not callable\n",
      "    self._target(*self._args, **self._kwargs)\n",
      "TypeError: 'Thread' object is not callable\n",
      "Exception in thread Thread-150:\n",
      "Traceback (most recent call last):\n",
      "  File \"C:\\Users\\Ishika\\anaconda3\\lib\\threading.py\", line 932, in _bootstrap_inner\n",
      "Exception in thread Thread-151:\n",
      "Traceback (most recent call last):\n",
      "  File \"C:\\Users\\Ishika\\anaconda3\\lib\\threading.py\", line 932, in _bootstrap_inner\n",
      "        self.run()\n",
      "  File \"C:\\Users\\Ishika\\anaconda3\\lib\\threading.py\", line 870, in run\n",
      "self.run()\n",
      "  File \"C:\\Users\\Ishika\\anaconda3\\lib\\threading.py\", line 870, in run\n",
      "        self._target(*self._args, **self._kwargs)\n",
      "TypeError: 'Thread' object is not callable\n",
      "self._target(*self._args, **self._kwargs)\n",
      "TypeError: 'Thread' object is not callable\n",
      "Exception in thread Thread-152:\n",
      "Traceback (most recent call last):\n",
      "  File \"C:\\Users\\Ishika\\anaconda3\\lib\\threading.py\", line 932, in _bootstrap_inner\n",
      "Exception in thread Thread-153:\n",
      "Traceback (most recent call last):\n",
      "  File \"C:\\Users\\Ishika\\anaconda3\\lib\\threading.py\", line 932, in _bootstrap_inner\n",
      "        self.run()\n",
      "  File \"C:\\Users\\Ishika\\anaconda3\\lib\\threading.py\", line 870, in run\n",
      "self.run()\n",
      "  File \"C:\\Users\\Ishika\\anaconda3\\lib\\threading.py\", line 870, in run\n",
      "    self._target(*self._args, **self._kwargs)\n",
      "TypeError: 'Thread' object is not callable\n",
      "    self._target(*self._args, **self._kwargs)\n",
      "TypeError: 'Thread' object is not callable\n",
      "Exception in thread Thread-154:\n",
      "Traceback (most recent call last):\n",
      "  File \"C:\\Users\\Ishika\\anaconda3\\lib\\threading.py\", line 932, in _bootstrap_inner\n",
      "Exception in thread Thread-155:\n",
      "Traceback (most recent call last):\n",
      "  File \"C:\\Users\\Ishika\\anaconda3\\lib\\threading.py\", line 932, in _bootstrap_inner\n",
      "    self.run()\n",
      "  File \"C:\\Users\\Ishika\\anaconda3\\lib\\threading.py\", line 870, in run\n",
      "    self.run()\n",
      "  File \"C:\\Users\\Ishika\\anaconda3\\lib\\threading.py\", line 870, in run\n",
      "    self._target(*self._args, **self._kwargs)\n",
      "TypeError: 'Thread' object is not callable\n",
      "    self._target(*self._args, **self._kwargs)\n",
      "TypeError: 'Thread' object is not callable\n",
      "Exception in thread Thread-156:\n",
      "Traceback (most recent call last):\n",
      "  File \"C:\\Users\\Ishika\\anaconda3\\lib\\threading.py\", line 932, in _bootstrap_inner\n",
      "Exception in thread Thread-157:\n",
      "Traceback (most recent call last):\n",
      "  File \"C:\\Users\\Ishika\\anaconda3\\lib\\threading.py\", line 932, in _bootstrap_inner\n",
      "    self.run()\n",
      "  File \"C:\\Users\\Ishika\\anaconda3\\lib\\threading.py\", line 870, in run\n",
      "    self.run()\n",
      "  File \"C:\\Users\\Ishika\\anaconda3\\lib\\threading.py\", line 870, in run\n",
      "    self._target(*self._args, **self._kwargs)\n",
      "TypeError: 'Thread' object is not callable\n",
      "    self._target(*self._args, **self._kwargs)\n",
      "TypeError: 'Thread' object is not callable\n",
      "Exception in thread Thread-158:\n",
      "Traceback (most recent call last):\n",
      "  File \"C:\\Users\\Ishika\\anaconda3\\lib\\threading.py\", line 932, in _bootstrap_inner\n",
      "Exception in thread Thread-159:\n",
      "Traceback (most recent call last):\n",
      "  File \"C:\\Users\\Ishika\\anaconda3\\lib\\threading.py\", line 932, in _bootstrap_inner\n",
      "    self.run()    \n",
      "  File \"C:\\Users\\Ishika\\anaconda3\\lib\\threading.py\", line 870, in run\n",
      "self.run()\n",
      "  File \"C:\\Users\\Ishika\\anaconda3\\lib\\threading.py\", line 870, in run\n",
      "        self._target(*self._args, **self._kwargs)\n",
      "TypeError: 'Thread' object is not callable\n",
      "self._target(*self._args, **self._kwargs)\n",
      "TypeError: 'Thread' object is not callable\n",
      "Exception in thread Thread-160:\n",
      "Traceback (most recent call last):\n",
      "  File \"C:\\Users\\Ishika\\anaconda3\\lib\\threading.py\", line 932, in _bootstrap_inner\n",
      "Exception in thread Thread-161:\n",
      "Traceback (most recent call last):\n",
      "  File \"C:\\Users\\Ishika\\anaconda3\\lib\\threading.py\", line 932, in _bootstrap_inner\n",
      "    self.run()\n",
      "  File \"C:\\Users\\Ishika\\anaconda3\\lib\\threading.py\", line 870, in run\n",
      "    self.run()\n",
      "  File \"C:\\Users\\Ishika\\anaconda3\\lib\\threading.py\", line 870, in run\n",
      "    self._target(*self._args, **self._kwargs)\n",
      "TypeError: 'Thread' object is not callable\n",
      "    self._target(*self._args, **self._kwargs)\n",
      "TypeError: 'Thread' object is not callable\n",
      "Exception in thread Thread-162:\n",
      "Traceback (most recent call last):\n",
      "  File \"C:\\Users\\Ishika\\anaconda3\\lib\\threading.py\", line 932, in _bootstrap_inner\n",
      "Exception in thread Thread-163:\n",
      "Traceback (most recent call last):\n",
      "  File \"C:\\Users\\Ishika\\anaconda3\\lib\\threading.py\", line 932, in _bootstrap_inner\n",
      "        self.run()\n",
      "  File \"C:\\Users\\Ishika\\anaconda3\\lib\\threading.py\", line 870, in run\n",
      "self.run()\n",
      "  File \"C:\\Users\\Ishika\\anaconda3\\lib\\threading.py\", line 870, in run\n",
      "    self._target(*self._args, **self._kwargs)\n",
      "TypeError: 'Thread' object is not callable\n",
      "    self._target(*self._args, **self._kwargs)\n",
      "TypeError: 'Thread' object is not callable\n",
      "Exception in thread Thread-164:\n",
      "Traceback (most recent call last):\n",
      "  File \"C:\\Users\\Ishika\\anaconda3\\lib\\threading.py\", line 932, in _bootstrap_inner\n",
      "Exception in thread Thread-165:\n",
      "Traceback (most recent call last):\n",
      "  File \"C:\\Users\\Ishika\\anaconda3\\lib\\threading.py\", line 932, in _bootstrap_inner\n",
      "    self.run()\n",
      "  File \"C:\\Users\\Ishika\\anaconda3\\lib\\threading.py\", line 870, in run\n",
      "    self.run()\n",
      "  File \"C:\\Users\\Ishika\\anaconda3\\lib\\threading.py\", line 870, in run\n",
      "    self._target(*self._args, **self._kwargs)\n",
      "TypeError: 'Thread' object is not callable\n",
      "    self._target(*self._args, **self._kwargs)\n",
      "TypeError: 'Thread' object is not callable\n",
      "Exception in thread Exception in thread Thread-167:\n",
      "Traceback (most recent call last):\n",
      "  File \"C:\\Users\\Ishika\\anaconda3\\lib\\threading.py\", line 932, in _bootstrap_inner\n",
      "Thread-166:\n",
      "Traceback (most recent call last):\n",
      "  File \"C:\\Users\\Ishika\\anaconda3\\lib\\threading.py\", line 932, in _bootstrap_inner\n",
      "    self.run()\n",
      "  File \"C:\\Users\\Ishika\\anaconda3\\lib\\threading.py\", line 870, in run\n",
      "    self.run()\n",
      "  File \"C:\\Users\\Ishika\\anaconda3\\lib\\threading.py\", line 870, in run\n",
      "    self._target(*self._args, **self._kwargs)\n",
      "TypeError: 'Thread' object is not callable\n"
     ]
    },
    {
     "name": "stderr",
     "output_type": "stream",
     "text": [
      "    self._target(*self._args, **self._kwargs)\n",
      "TypeError: 'Thread' object is not callable\n",
      "Exception in thread Thread-168:\n",
      "Traceback (most recent call last):\n",
      "  File \"C:\\Users\\Ishika\\anaconda3\\lib\\threading.py\", line 932, in _bootstrap_inner\n",
      "Exception in thread Thread-169:\n",
      "Traceback (most recent call last):\n",
      "  File \"C:\\Users\\Ishika\\anaconda3\\lib\\threading.py\", line 932, in _bootstrap_inner\n",
      "        self.run()\n",
      "  File \"C:\\Users\\Ishika\\anaconda3\\lib\\threading.py\", line 870, in run\n",
      "self.run()\n",
      "  File \"C:\\Users\\Ishika\\anaconda3\\lib\\threading.py\", line 870, in run\n",
      "    self._target(*self._args, **self._kwargs)\n",
      "TypeError: 'Thread' object is not callable\n",
      "    self._target(*self._args, **self._kwargs)\n",
      "TypeError: 'Thread' object is not callable\n",
      "Exception in thread Thread-170:\n",
      "Traceback (most recent call last):\n",
      "  File \"C:\\Users\\Ishika\\anaconda3\\lib\\threading.py\", line 932, in _bootstrap_inner\n",
      "Exception in thread Thread-171:\n",
      "Traceback (most recent call last):\n",
      "  File \"C:\\Users\\Ishika\\anaconda3\\lib\\threading.py\", line 932, in _bootstrap_inner\n",
      "    self.run()\n",
      "  File \"C:\\Users\\Ishika\\anaconda3\\lib\\threading.py\", line 870, in run\n",
      "    self.run()\n",
      "  File \"C:\\Users\\Ishika\\anaconda3\\lib\\threading.py\", line 870, in run\n",
      "    self._target(*self._args, **self._kwargs)\n",
      "TypeError: 'Thread' object is not callable\n",
      "    self._target(*self._args, **self._kwargs)\n",
      "TypeError: 'Thread' object is not callable\n",
      "Exception in thread Thread-172:\n",
      "Traceback (most recent call last):\n",
      "  File \"C:\\Users\\Ishika\\anaconda3\\lib\\threading.py\", line 932, in _bootstrap_inner\n",
      "Exception in thread Thread-173:\n",
      "Traceback (most recent call last):\n",
      "  File \"C:\\Users\\Ishika\\anaconda3\\lib\\threading.py\", line 932, in _bootstrap_inner\n",
      "    self.run()\n",
      "  File \"C:\\Users\\Ishika\\anaconda3\\lib\\threading.py\", line 870, in run\n",
      "    self.run()\n",
      "  File \"C:\\Users\\Ishika\\anaconda3\\lib\\threading.py\", line 870, in run\n",
      "    self._target(*self._args, **self._kwargs)\n",
      "TypeError: 'Thread' object is not callable\n",
      "    self._target(*self._args, **self._kwargs)\n",
      "TypeError: 'Thread' object is not callable\n",
      "Exception in thread Thread-174:\n",
      "Traceback (most recent call last):\n",
      "  File \"C:\\Users\\Ishika\\anaconda3\\lib\\threading.py\", line 932, in _bootstrap_inner\n",
      "Exception in thread Thread-175:\n",
      "Traceback (most recent call last):\n",
      "  File \"C:\\Users\\Ishika\\anaconda3\\lib\\threading.py\", line 932, in _bootstrap_inner\n",
      "    self.run()\n",
      "    self.run()\n",
      "  File \"C:\\Users\\Ishika\\anaconda3\\lib\\threading.py\", line 870, in run\n",
      "  File \"C:\\Users\\Ishika\\anaconda3\\lib\\threading.py\", line 870, in run\n",
      "    self._target(*self._args, **self._kwargs)\n",
      "TypeError: 'Thread' object is not callable\n",
      "    self._target(*self._args, **self._kwargs)\n",
      "TypeError: 'Thread' object is not callable\n",
      "Exception in thread Thread-176:\n",
      "Traceback (most recent call last):\n",
      "  File \"C:\\Users\\Ishika\\anaconda3\\lib\\threading.py\", line 932, in _bootstrap_inner\n",
      "Exception in thread Thread-177:\n",
      "Traceback (most recent call last):\n",
      "  File \"C:\\Users\\Ishika\\anaconda3\\lib\\threading.py\", line 932, in _bootstrap_inner\n",
      "        self.run()\n",
      "  File \"C:\\Users\\Ishika\\anaconda3\\lib\\threading.py\", line 870, in run\n",
      "self.run()\n",
      "  File \"C:\\Users\\Ishika\\anaconda3\\lib\\threading.py\", line 870, in run\n",
      "        self._target(*self._args, **self._kwargs)\n",
      "TypeError: 'Thread' object is not callable\n",
      "self._target(*self._args, **self._kwargs)\n",
      "TypeError: 'Thread' object is not callable\n",
      "Exception in thread Thread-178:\n",
      "Traceback (most recent call last):\n",
      "  File \"C:\\Users\\Ishika\\anaconda3\\lib\\threading.py\", line 932, in _bootstrap_inner\n",
      "Exception in thread Thread-179:\n",
      "Traceback (most recent call last):\n",
      "  File \"C:\\Users\\Ishika\\anaconda3\\lib\\threading.py\", line 932, in _bootstrap_inner\n",
      "    self.run()\n",
      "  File \"C:\\Users\\Ishika\\anaconda3\\lib\\threading.py\", line 870, in run\n",
      "    self.run()\n",
      "  File \"C:\\Users\\Ishika\\anaconda3\\lib\\threading.py\", line 870, in run\n",
      "    self._target(*self._args, **self._kwargs)\n",
      "TypeError: 'Thread' object is not callable\n",
      "    self._target(*self._args, **self._kwargs)\n",
      "TypeError: 'Thread' object is not callable\n",
      "Exception in thread Exception in thread Thread-181:\n",
      "Traceback (most recent call last):\n",
      "  File \"C:\\Users\\Ishika\\anaconda3\\lib\\threading.py\", line 932, in _bootstrap_inner\n",
      "Thread-180:\n",
      "Traceback (most recent call last):\n",
      "  File \"C:\\Users\\Ishika\\anaconda3\\lib\\threading.py\", line 932, in _bootstrap_inner\n",
      "    self.run()\n",
      "  File \"C:\\Users\\Ishika\\anaconda3\\lib\\threading.py\", line 870, in run\n",
      "    self.run()\n",
      "  File \"C:\\Users\\Ishika\\anaconda3\\lib\\threading.py\", line 870, in run\n",
      "    self._target(*self._args, **self._kwargs)\n",
      "TypeError: 'Thread' object is not callable\n",
      "    self._target(*self._args, **self._kwargs)\n",
      "TypeError: 'Thread' object is not callable\n",
      "Exception in thread Thread-182:\n",
      "Traceback (most recent call last):\n",
      "  File \"C:\\Users\\Ishika\\anaconda3\\lib\\threading.py\", line 932, in _bootstrap_inner\n",
      "Exception in thread Thread-183:\n",
      "Traceback (most recent call last):\n",
      "  File \"C:\\Users\\Ishika\\anaconda3\\lib\\threading.py\", line 932, in _bootstrap_inner\n",
      "    self.run()\n",
      "  File \"C:\\Users\\Ishika\\anaconda3\\lib\\threading.py\", line 870, in run\n",
      "    self.run()\n",
      "  File \"C:\\Users\\Ishika\\anaconda3\\lib\\threading.py\", line 870, in run\n",
      "    self._target(*self._args, **self._kwargs)\n",
      "TypeError: 'Thread' object is not callable\n",
      "    self._target(*self._args, **self._kwargs)\n",
      "TypeError: 'Thread' object is not callable\n",
      "Exception in thread Thread-184:\n",
      "Traceback (most recent call last):\n",
      "  File \"C:\\Users\\Ishika\\anaconda3\\lib\\threading.py\", line 932, in _bootstrap_inner\n",
      "Exception in thread Thread-185:\n",
      "Traceback (most recent call last):\n",
      "  File \"C:\\Users\\Ishika\\anaconda3\\lib\\threading.py\", line 932, in _bootstrap_inner\n",
      "    self.run()\n",
      "  File \"C:\\Users\\Ishika\\anaconda3\\lib\\threading.py\", line 870, in run\n",
      "    self.run()\n",
      "  File \"C:\\Users\\Ishika\\anaconda3\\lib\\threading.py\", line 870, in run\n",
      "        self._target(*self._args, **self._kwargs)\n",
      "TypeError: 'Thread' object is not callable\n",
      "self._target(*self._args, **self._kwargs)\n",
      "TypeError: 'Thread' object is not callable\n",
      "Exception in thread Thread-186:\n",
      "Traceback (most recent call last):\n",
      "  File \"C:\\Users\\Ishika\\anaconda3\\lib\\threading.py\", line 932, in _bootstrap_inner\n",
      "Exception in thread Thread-187:\n",
      "Traceback (most recent call last):\n",
      "  File \"C:\\Users\\Ishika\\anaconda3\\lib\\threading.py\", line 932, in _bootstrap_inner\n",
      "    self.run()\n",
      "  File \"C:\\Users\\Ishika\\anaconda3\\lib\\threading.py\", line 870, in run\n",
      "    self.run()\n",
      "  File \"C:\\Users\\Ishika\\anaconda3\\lib\\threading.py\", line 870, in run\n",
      "    self._target(*self._args, **self._kwargs)\n",
      "TypeError: 'Thread' object is not callable\n",
      "    self._target(*self._args, **self._kwargs)\n",
      "TypeError: 'Thread' object is not callable\n",
      "Exception in thread Exception in thread Thread-188:\n",
      "Traceback (most recent call last):\n",
      "  File \"C:\\Users\\Ishika\\anaconda3\\lib\\threading.py\", line 932, in _bootstrap_inner\n",
      "Thread-189:\n",
      "Traceback (most recent call last):\n",
      "  File \"C:\\Users\\Ishika\\anaconda3\\lib\\threading.py\", line 932, in _bootstrap_inner\n",
      "        self.run()\n",
      "  File \"C:\\Users\\Ishika\\anaconda3\\lib\\threading.py\", line 870, in run\n",
      "self.run()\n",
      "  File \"C:\\Users\\Ishika\\anaconda3\\lib\\threading.py\", line 870, in run\n",
      "        self._target(*self._args, **self._kwargs)\n",
      "TypeError: 'Thread' object is not callable\n",
      "self._target(*self._args, **self._kwargs)\n",
      "TypeError: 'Thread' object is not callable\n",
      "Exception in thread Thread-190:\n",
      "Traceback (most recent call last):\n",
      "  File \"C:\\Users\\Ishika\\anaconda3\\lib\\threading.py\", line 932, in _bootstrap_inner\n",
      "Exception in thread Thread-191:\n",
      "Traceback (most recent call last):\n",
      "  File \"C:\\Users\\Ishika\\anaconda3\\lib\\threading.py\", line 932, in _bootstrap_inner\n",
      "    self.run()\n",
      "  File \"C:\\Users\\Ishika\\anaconda3\\lib\\threading.py\", line 870, in run\n",
      "    self.run()\n",
      "  File \"C:\\Users\\Ishika\\anaconda3\\lib\\threading.py\", line 870, in run\n",
      "    self._target(*self._args, **self._kwargs)\n",
      "TypeError: 'Thread' object is not callable\n",
      "    self._target(*self._args, **self._kwargs)\n",
      "TypeError: 'Thread' object is not callable\n",
      "Exception in thread Thread-192:\n",
      "Traceback (most recent call last):\n",
      "  File \"C:\\Users\\Ishika\\anaconda3\\lib\\threading.py\", line 932, in _bootstrap_inner\n",
      "Exception in thread Thread-193:\n",
      "Traceback (most recent call last):\n",
      "  File \"C:\\Users\\Ishika\\anaconda3\\lib\\threading.py\", line 932, in _bootstrap_inner\n",
      "    self.run()\n",
      "  File \"C:\\Users\\Ishika\\anaconda3\\lib\\threading.py\", line 870, in run\n",
      "    self.run()\n",
      "  File \"C:\\Users\\Ishika\\anaconda3\\lib\\threading.py\", line 870, in run\n",
      "    self._target(*self._args, **self._kwargs)\n",
      "TypeError: 'Thread' object is not callable\n"
     ]
    },
    {
     "name": "stderr",
     "output_type": "stream",
     "text": [
      "    self._target(*self._args, **self._kwargs)\n",
      "TypeError: 'Thread' object is not callable\n",
      "Exception in thread Thread-194:\n",
      "Traceback (most recent call last):\n",
      "  File \"C:\\Users\\Ishika\\anaconda3\\lib\\threading.py\", line 932, in _bootstrap_inner\n",
      "Exception in thread Thread-195:\n",
      "Traceback (most recent call last):\n",
      "  File \"C:\\Users\\Ishika\\anaconda3\\lib\\threading.py\", line 932, in _bootstrap_inner\n",
      "    self.run()\n",
      "  File \"C:\\Users\\Ishika\\anaconda3\\lib\\threading.py\", line 870, in run\n",
      "        self._target(*self._args, **self._kwargs)\n",
      "TypeError: 'Thread' object is not callable\n",
      "self.run()\n",
      "  File \"C:\\Users\\Ishika\\anaconda3\\lib\\threading.py\", line 870, in run\n",
      "    self._target(*self._args, **self._kwargs)\n",
      "TypeError: 'Thread' object is not callable\n",
      "Exception in thread Thread-196:\n",
      "Traceback (most recent call last):\n",
      "  File \"C:\\Users\\Ishika\\anaconda3\\lib\\threading.py\", line 932, in _bootstrap_inner\n",
      "Exception in thread Thread-197:\n",
      "Traceback (most recent call last):\n",
      "  File \"C:\\Users\\Ishika\\anaconda3\\lib\\threading.py\", line 932, in _bootstrap_inner\n",
      "    self.run()\n",
      "  File \"C:\\Users\\Ishika\\anaconda3\\lib\\threading.py\", line 870, in run\n",
      "    self.run()\n",
      "  File \"C:\\Users\\Ishika\\anaconda3\\lib\\threading.py\", line 870, in run\n",
      "    self._target(*self._args, **self._kwargs)\n",
      "TypeError: 'Thread' object is not callable\n",
      "    self._target(*self._args, **self._kwargs)\n",
      "TypeError: 'Thread' object is not callable\n",
      "Exception in thread Thread-198:\n",
      "Traceback (most recent call last):\n",
      "  File \"C:\\Users\\Ishika\\anaconda3\\lib\\threading.py\", line 932, in _bootstrap_inner\n",
      "Exception in thread Thread-199:\n",
      "Traceback (most recent call last):\n",
      "  File \"C:\\Users\\Ishika\\anaconda3\\lib\\threading.py\", line 932, in _bootstrap_inner\n",
      "    self.run()\n",
      "  File \"C:\\Users\\Ishika\\anaconda3\\lib\\threading.py\", line 870, in run\n",
      "    self.run()\n",
      "  File \"C:\\Users\\Ishika\\anaconda3\\lib\\threading.py\", line 870, in run\n",
      "    self._target(*self._args, **self._kwargs)\n",
      "TypeError: 'Thread' object is not callable\n",
      "    self._target(*self._args, **self._kwargs)\n",
      "TypeError: 'Thread' object is not callable\n",
      "Exception in thread Exception in thread Thread-201:\n",
      "Traceback (most recent call last):\n",
      "  File \"C:\\Users\\Ishika\\anaconda3\\lib\\threading.py\", line 932, in _bootstrap_inner\n",
      "Thread-200:\n",
      "Traceback (most recent call last):\n",
      "  File \"C:\\Users\\Ishika\\anaconda3\\lib\\threading.py\", line 932, in _bootstrap_inner\n",
      "    self.run()\n",
      "  File \"C:\\Users\\Ishika\\anaconda3\\lib\\threading.py\", line 870, in run\n",
      "    self.run()\n",
      "  File \"C:\\Users\\Ishika\\anaconda3\\lib\\threading.py\", line 870, in run\n",
      "    self._target(*self._args, **self._kwargs)\n",
      "TypeError: 'Thread' object is not callable\n",
      "    self._target(*self._args, **self._kwargs)\n",
      "TypeError: 'Thread' object is not callable\n",
      "Exception in thread Thread-202:\n",
      "Traceback (most recent call last):\n",
      "  File \"C:\\Users\\Ishika\\anaconda3\\lib\\threading.py\", line 932, in _bootstrap_inner\n",
      "Exception in thread Thread-203:\n",
      "Traceback (most recent call last):\n",
      "  File \"C:\\Users\\Ishika\\anaconda3\\lib\\threading.py\", line 932, in _bootstrap_inner\n",
      "        self.run()\n",
      "  File \"C:\\Users\\Ishika\\anaconda3\\lib\\threading.py\", line 870, in run\n",
      "self.run()\n",
      "  File \"C:\\Users\\Ishika\\anaconda3\\lib\\threading.py\", line 870, in run\n",
      "        self._target(*self._args, **self._kwargs)\n",
      "TypeError: 'Thread' object is not callableself._target(*self._args, **self._kwargs)\n",
      "TypeError: 'Thread' object is not callable\n",
      "\n",
      "Exception in thread Thread-204:\n",
      "Traceback (most recent call last):\n",
      "  File \"C:\\Users\\Ishika\\anaconda3\\lib\\threading.py\", line 932, in _bootstrap_inner\n",
      "Exception in thread Thread-205:\n",
      "Traceback (most recent call last):\n",
      "  File \"C:\\Users\\Ishika\\anaconda3\\lib\\threading.py\", line 932, in _bootstrap_inner\n",
      "    self.run()\n",
      "  File \"C:\\Users\\Ishika\\anaconda3\\lib\\threading.py\", line 870, in run\n",
      "    self.run()\n",
      "  File \"C:\\Users\\Ishika\\anaconda3\\lib\\threading.py\", line 870, in run\n",
      "    self._target(*self._args, **self._kwargs)\n",
      "TypeError: 'Thread' object is not callable\n",
      "    self._target(*self._args, **self._kwargs)\n",
      "TypeError: 'Thread' object is not callable\n",
      "Exception in thread Thread-206:\n",
      "Traceback (most recent call last):\n",
      "  File \"C:\\Users\\Ishika\\anaconda3\\lib\\threading.py\", line 932, in _bootstrap_inner\n",
      "Exception in thread Thread-207:\n",
      "Traceback (most recent call last):\n",
      "  File \"C:\\Users\\Ishika\\anaconda3\\lib\\threading.py\", line 932, in _bootstrap_inner\n",
      "    self.run()\n",
      "  File \"C:\\Users\\Ishika\\anaconda3\\lib\\threading.py\", line 870, in run\n",
      "    self.run()\n",
      "  File \"C:\\Users\\Ishika\\anaconda3\\lib\\threading.py\", line 870, in run\n",
      "    self._target(*self._args, **self._kwargs)\n",
      "TypeError: 'Thread' object is not callable\n",
      "    self._target(*self._args, **self._kwargs)\n",
      "TypeError: 'Thread' object is not callable\n",
      "Exception in thread Exception in thread Thread-208:\n",
      "Traceback (most recent call last):\n",
      "  File \"C:\\Users\\Ishika\\anaconda3\\lib\\threading.py\", line 932, in _bootstrap_inner\n",
      "Thread-209:\n",
      "Traceback (most recent call last):\n",
      "  File \"C:\\Users\\Ishika\\anaconda3\\lib\\threading.py\", line 932, in _bootstrap_inner\n",
      "        self.run()\n",
      "  File \"C:\\Users\\Ishika\\anaconda3\\lib\\threading.py\", line 870, in run\n",
      "self.run()\n",
      "  File \"C:\\Users\\Ishika\\anaconda3\\lib\\threading.py\", line 870, in run\n",
      "    self._target(*self._args, **self._kwargs)\n",
      "    self._target(*self._args, **self._kwargs)\n",
      "TypeError: 'Thread' object is not callable\n",
      "TypeError: 'Thread' object is not callable\n"
     ]
    }
   ],
   "source": [
    "import cv2\n",
    "import numpy as np\n",
    "import os\n",
    "\n",
    "\n",
    "face_classifier = cv2.CascadeClassifier('haarcascade_frontalface_default.xml')\n",
    "\n",
    "def face_detector(img, size=0.5):\n",
    "    \n",
    "    # Convert image to grayscale\n",
    "    gray = cv2.cvtColor(img,cv2.COLOR_BGR2GRAY)\n",
    "    faces = face_classifier.detectMultiScale(gray, 1.3, 5)\n",
    "    if faces is ():\n",
    "        return img, []\n",
    "    \n",
    "    \n",
    "    for (x,y,w,h) in faces:\n",
    "        cv2.rectangle(img,(x,y),(x+w,y+h),(0,255,255),2)\n",
    "        roi = img[y:y+h, x:x+w]\n",
    "        roi = cv2.resize(roi, (200, 200))\n",
    "    return img, roi\n",
    "\n",
    "\n",
    "# Open Webcam\n",
    "cap = cv2.VideoCapture(0)\n",
    "\n",
    "while True:\n",
    "\n",
    "    ret, frame = cap.read()\n",
    "    \n",
    "    image, face = face_detector(frame)\n",
    "    \n",
    "    try:\n",
    "        face = cv2.cvtColor(face, cv2.COLOR_BGR2GRAY)\n",
    "\n",
    "        # Pass face to prediction model\n",
    "        # \"results\" comprises of a tuple containing the label and the confidence value\n",
    "        results = ishika_model.predict(face)\n",
    "        # harry_model.predict(face)\n",
    "        \n",
    "        if results[1] < 500:\n",
    "            confidence = int( 100 * (1 - (results[1])/650) )\n",
    "            display_string = str(confidence) + '% Confident it is User'\n",
    "            \n",
    "        cv2.putText(image, display_string, (100, 120), cv2.FONT_HERSHEY_COMPLEX, 1, (255,120,150), 2)\n",
    "        \n",
    "        if confidence > 90:\n",
    "            cv2.putText(image, \"Hey Ishika\", (250, 450), cv2.FONT_HERSHEY_COMPLEX, 1, (0,255,0), 2)\n",
    "            cv2.imshow('Face Recognition', image )\n",
    "           \n",
    "             #For sending mail\n",
    "            mail=threading.Thread(target=mail)\n",
    "            mail.start()\n",
    "            #For Whatsapp\n",
    "            whatsapp=threading.Thread(target=whatsapp)\n",
    "            whatsapp.start()\n",
    "            \n",
    "        \n",
    "        \n",
    "        else:\n",
    "            \n",
    "            cv2.putText(image, \"I dont know, how r u\", (250, 450), cv2.FONT_HERSHEY_COMPLEX, 1, (0,0,255), 2)\n",
    "            cv2.imshow('Face Recognition', image )\n",
    "\n",
    "    except:\n",
    "        cv2.putText(image, \"No Face Found\", (220, 120) , cv2.FONT_HERSHEY_COMPLEX, 1, (0,0,255), 2)\n",
    "        cv2.putText(image, \"looking for face\", (250, 450), cv2.FONT_HERSHEY_COMPLEX, 1, (0,0,255), 2)\n",
    "        cv2.imshow('Face Recognition', image )\n",
    "        pass\n",
    "        \n",
    "    if cv2.waitKey(1) == 13: #13 is the Enter Key\n",
    "        break\n",
    "        \n",
    "cap.release()\n",
    "cv2.destroyAllWindows()     "
   ]
  },
  {
   "cell_type": "code",
   "execution_count": null,
   "id": "db1009e3",
   "metadata": {},
   "outputs": [],
   "source": []
  }
 ],
 "metadata": {
  "kernelspec": {
   "display_name": "Python 3",
   "language": "python",
   "name": "python3"
  },
  "language_info": {
   "codemirror_mode": {
    "name": "ipython",
    "version": 3
   },
   "file_extension": ".py",
   "mimetype": "text/x-python",
   "name": "python",
   "nbconvert_exporter": "python",
   "pygments_lexer": "ipython3",
   "version": "3.8.8"
  }
 },
 "nbformat": 4,
 "nbformat_minor": 5
}
